Workbook

Sheet 2026_Values
B1: 01-01-2026 | C1: 02-01-2026 | D1: 03-01-2026 | E1: 04-01-2026 | F1: 05-01-2026 | G1: 06-01-2026 | H1: 07-01-2026 | I1: 08-01-2026 | J1: 09-01-2026 | K1: 10-01-2026 | L1: 11-01-2026 | M1: 12-01-2026 | N1: 13-01-2026 | O1: 14-01-2026 | P1: 15-01-2026 | Q1: 16-01-2026 | R1: 17-01-2026 | S1: 18-01-2026 | T1: 19-01-2026 | U1: 20-01-2026 | V1: 21-01-2026 | W1: 22-01-2026 | X1: 23-01-2026 | Y1: 24-01-2026 | Z1: 25-01-2026 | AA1: 26-01-2026 | AB1: 27-01-2026 | AC1: 28-01-2026 | AD1: 29-01-2026 | AE1: 30-01-2026 | AF1: 31-01-2026 | AG1: 01-02-2026 | AH1: 02-02-2026 | AI1: 03-02-2026 | AJ1: 04-02-2026 | AK1: 05-02-2026 | AL1: 06-02-2026 | AM1: 07-02-2026 | AN1: 08-02-2026 | AO1: 09-02-2026 | AP1: 10-02-2026 | AQ1: 11-02-2026 | AR1: 12-02-2026 | AS1: 13-02-2026 | AT1: 14-02-2026 | AU1: 15-02-2026 | AV1: 16-02-2026 | AW1: 17-02-2026 | AX1: 18-02-2026 | AY1: 19-02-2026 | AZ1: 20-02-2026 | BA1: 21-02-2026 | BB1: 22-02-2026 | BC1: 23-02-2026 | BD1: 24-02-2026 | BE1: 25-02-2026 | BF1: 26-02-2026 | BG1: 27-02-2026 | BH1: 28-02-2026 | BI1: 01-03-2026 | BJ1: 02-03-2026 | BK1: 03-03-2026 | BL1: 04-03-2026 | BM1: 05-03-2026 | BN1: 06-03-2026 | BO1: 07-03-2026 | BP1: 08-03-2026 | BQ1: 09-03-2026 | BR1: 10-03-2026 | BS1: 11-03-2026 | BT1: 12-03-2026 | BU1: 13-03-2026 | BV1: 14-03-2026 | BW1: 15-03-2026 | BX1: 16-03-2026 | BY1: 17-03-2026 | BZ1: 18-03-2026 | CA1: 19-03-2026 | CB1: 20-03-2026 | CC1: 21-03-2026 | CD1: 22-03-2026 | CE1: 23-03-2026 | CF1: 24-03-2026 | CG1: 25-03-2026 | CH1: 26-03-2026 | CI1: 27-03-2026 | CJ1: 28-03-2026 | CK1: 29-03-2026 | CL1: 30-03-2026 | CM1: 31-03-2026 | CN1: 01-04-2026 | CO1: 02-04-2026 | CP1: 03-04-2026 | CQ1: 04-04-2026 | CR1: 05-04-2026 | CS1: 06-04-2026 | CT1: 07-04-2026 | CU1: 08-04-2026 | CV1: 09-04-2026 | CW1: 10-04-2026 | CX1: 11-04-2026 | CY1: 12-04-2026 | CZ1: 13-04-2026 | DA1: 14-04-2026 | DB1: 15-04-2026 | DC1: 16-04-2026 | DD1: 17-04-2026 | DE1: 18-04-2026 | DF1: 19-04-2026 | DG1: 20-04-2026 | DH1: 21-04-2026 | DI1: 22-04-2026 | DJ1: 23-04-2026 | DK1: 24-04-2026 | DL1: 25-04-2026 | DM1: 26-04-2026 | DN1: 27-04-2026 | DO1: 28-04-2026 | DP1: 29-04-2026 | DQ1: 30-04-2026 | DR1: 01-05-2026 | DS1: 02-05-2026 | DT1: 03-05-2026 | DU1: 04-05-2026 | DV1: 05-05-2026 | DW1: 06-05-2026 | DX1: 07-05-2026 | DY1: 08-05-2026 | DZ1: 09-05-2026 | EA1: 10-05-2026 | EB1: 11-05-2026 | EC1: 12-05-2026 | ED1: 13-05-2026 | EE1: 14-05-2026 | EF1: 15-05-2026 | EG1: 16-05-2026 | EH1: 17-05-2026 | EI1: 18-05-2026 | EJ1: 19-05-2026 | EK1: 20-05-2026 | EL1: 21-05-2026 | EM1: 22-05-2026 | EN1: 23-05-2026 | EO1: 24-05-2026 | EP1: 25-05-2026 | EQ1: 26-05-2026 | ER1: 27-05-2026 | ES1: 28-05-2026 | ET1: 29-05-2026 | EU1: 30-05-2026 | EV1: 31-05-2026 | EW1: 01-06-2026 | EX1: 02-06-2026 | EY1: 03-06-2026 | EZ1: 04-06-2026 | FA1: 05-06-2026 | FB1: 06-06-2026 | FC1: 07-06-2026 | FD1: 08-06-2026 | FE1: 09-06-2026 | FF1: 10-06-2026 | FG1: 11-06-2026 | FH1: 12-06-2026 | FI1: 13-06-2026 | FJ1: 14-06-2026 | FK1: 15-06-2026 | FL1: 16-06-2026 | FM1: 17-06-2026 | FN1: 18-06-2026 | FO1: 19-06-2026 | FP1: 20-06-2026 | FQ1: 21-06-2026 | FR1: 22-06-2026 | FS1: 23-06-2026 | FT1: 24-06-2026 | FU1: 25-06-2026 | FV1: 26-06-2026 | FW1: 27-06-2026 | FX1: 28-06-2026 | FY1: 29-06-2026 | FZ1: 30-06-2026 | GA1: 01-07-2026 | GB1: 02-07-2026 | GC1: 03-07-2026 | GD1: 04-07-2026 | GE1: 05-07-2026 | GF1: 06-07-2026 | GG1: 07-07-2026 | GH1: 08-07-2026 | GI1: 09-07-2026 | GJ1: 10-07-2026 | GK1: 11-07-2026 | GL1: 12-07-2026 | GM1: 13-07-2026 | GN1: 14-07-2026 | GO1: 15-07-2026 | GP1: 16-07-2026 | GQ1: 17-07-2026 | GR1: 18-07-2026 | GS1: 19-07-2026 | GT1: 20-07-2026 | GU1: 21-07-2026 | GV1: 22-07-2026 | GW1: 23-07-2026 | GX1: 24-07-2026 | GY1: 25-07-2026 | GZ1: 26-07-2026 | HA1: 27-07-2026 | HB1: 28-07-2026 | HC1: 29-07-2026 | HD1: 30-07-2026 | HE1: 31-07-2026 | HF1: 01-08-2026 | HG1: 02-08-2026 | HH1: 03-08-2026 | HI1: 04-08-2026 | HJ1: 05-08-2026 | HK1: 06-08-2026 | HL1: 07-08-2026 | HM1: 08-08-2026 | HN1: 09-08-2026 | HO1: 10-08-2026 | HP1: 11-08-2026 | HQ1: 12-08-2026 | HR1: 13-08-2026 | HS1: 14-08-2026 | HT1: 15-08-2026 | HU1: 16-08-2026 | HV1: 17-08-2026 | HW1: 18-08-2026 | HX1: 19-08-2026 | HY1: 20-08-2026 | HZ1: 21-08-2026 | IA1: 22-08-2026 | IB1: 23-08-2026 | IC1: 24-08-2026 | ID1: 25-08-2026 | IE1: 26-08-2026 | IF1: 27-08-2026 | IG1: 28-08-2026 | IH1: 29-08-2026 | II1: 30-08-2026 | IJ1: 31-08-2026 | IK1: 01-09-2026 | IL1: 02-09-2026 | IM1: 03-09-2026 | IN1: 04-09-2026 | IO1: 05-09-2026 | IP1: 06-09-2026 | IQ1: 07-09-2026 | IR1: 08-09-2026 | IS1: 09-09-2026 | IT1: 10-09-2026 | IU1: 11-09-2026 | IV1: 12-09-2026 | IW1: 13-09-2026 | IX1: 14-09-2026 | IY1: 15-09-2026 | IZ1: 16-09-2026 | JA1: 17-09-2026 | JB1: 18-09-2026 | JC1: 19-09-2026 | JD1: 20-09-2026 | JE1: 21-09-2026 | JF1: 22-09-2026 | JG1: 23-09-2026 | JH1: 24-09-2026 | JI1: 25-09-2026 | JJ1: 26-09-2026 | JK1: 27-09-2026 | JL1: 28-09-2026 | JM1: 29-09-2026 | JN1: 30-09-2026 | JO1: 01-10-2026 | JP1: 02-10-2026 | JQ1: 03-10-2026 | JR1: 04-10-2026 | JS1: 05-10-2026 | JT1: 06-10-2026 | JU1: 07-10-2026 | JV1: 08-10-2026 | JW1: 09-10-2026 | JX1: 10-10-2026 | JY1: 11-10-2026 | JZ1: 12-10-2026 | KA1: 13-10-2026 | KB1: 14-10-2026 | KC1: 15-10-2026 | KD1: 16-10-2026 | KE1: 17-10-2026 | KF1: 18-10-2026 | KG1: 19-10-2026 | KH1: 20-10-2026 | KI1: 21-10-2026 | KJ1: 22-10-2026 | KK1: 23-10-2026 | KL1: 24-10-2026 | KM1: 25-10-2026 | KN1: 26-10-2026 | KO1: 27-10-2026 | KP1: 28-10-2026 | KQ1: 29-10-2026 | KR1: 30-10-2026 | KS1: 31-10-2026 | KT1: 01-11-2026 | KU1: 02-11-2026 | KV1: 03-11-2026 | KW1: 04-11-2026 | KX1: 05-11-2026 | KY1: 06-11-2026 | KZ1: 07-11-2026 | LA1: 08-11-2026 | LB1: 09-11-2026 | LC1: 10-11-2026 | LD1: 11-11-2026 | LE1: 12-11-2026 | LF1: 13-11-2026 | LG1: 14-11-2026 | LH1: 15-11-2026 | LI1: 16-11-2026 | LJ1: 17-11-2026 | LK1: 18-11-2026 | LL1: 19-11-2026 | LM1: 20-11-2026 | LN1: 21-11-2026 | LO1: 22-11-2026 | LP1: 23-11-2026 | LQ1: 24-11-2026 | LR1: 25-11-2026 | LS1: 26-11-2026 | LT1: 27-11-2026 | LU1: 28-11-2026 | LV1: 29-11-2026 | LW1: 30-11-2026 | LX1: 01-12-2026 | LY1: 02-12-2026 | LZ1: 03-12-2026 | MA1: 04-12-2026 | MB1: 05-12-2026 | MC1: 06-12-2026 | MD1: 07-12-2026 | ME1: 08-12-2026 | MF1: 09-12-2026 | MG1: 10-12-2026 | MH1: 11-12-2026 | MI1: 12-12-2026 | MJ1: 13-12-2026 | MK1: 14-12-2026 | ML1: 15-12-2026 | MM1: 16-12-2026 | MN1: 17-12-2026 | MO1: 18-12-2026 | MP1: 19-12-2026 | MQ1: 20-12-2026 | MR1: 21-12-2026 | MS1: 22-12-2026 | MT1: 23-12-2026 | MU1: 24-12-2026 | MV1: 25-12-2026 | MW1: 26-12-2026 | MX1: 27-12-2026 | MY1: 28-12-2026 | MZ1: 29-12-2026 | NA1: 30-12-2026 | NB1: 31-12-2026 | NC1: Total
A2: Total revenue Parking | B2: 45 | C2: 30 | D2: 0 | E2: 0 | F2: 0 | G2: 0 | H2: 0 | I2: 0 | J2: 30 | K2: 15 | L2: 0 | M2: 0 | N2: 0 | O2: 15 | P2: 0 | Q2: 0 | R2: 0 | S2: 0 | T2: 0 | U2: 0 | V2: 0 | W2: 0 | X2: 0 | Y2: 0 | Z2: 0 | AA2: 0 | AB2: 0 | AC2: 0 | AD2: 0 | AE2: 0 | AF2: 15 | AG2: 0 | AH2: 15 | AI2: 0 | AJ2: 0 | AK2: 0 | AL2: 30 | AM2: 15 | AN2: 120 | AO2: 0 | AP2: 0 | AQ2: 30 | AR2: 0 | AS2: 150 | AT2: 240 | AU2: 0 | AV2: 0 | AW2: 0 | AX2: 0 | AY2: 0 | AZ2: 30 | BA2: 15 | BB2: 0 | BC2: 0 | BD2: 30 | BE2: 0 | BF2: 0 | BG2: 0 | BH2: 0 | BI2: 0 | BJ2: 0 | BK2: 0 | BL2: 0 | BM2: 0 | BN2: 0 | BO2: 0 | BP2: 0 | BQ2: 0 | BR2: 0 | BS2: 0 | BT2: 0 | BU2: 0 | BV2: 0 | BW2: 0 | BX2: 0 | BY2: 0 | BZ2: 0 | CA2: 0 | CB2: 0 | CC2: 0 | CD2: 0 | CE2: 0 | CF2: 0 | CG2: 0 | CH2: 0 | CI2: 0 | CJ2: 0 | CK2: 0 | CL2: 0 | CM2: 0 | CN2: 0 | CO2: 0 | CP2: 0 | CQ2: 0 | CR2: 0 | CS2: 0 | CT2: 0 | CU2: 0 | CV2: 0 | CW2: 0 | CX2: 0 | CY2: 0 | CZ2: 0 | DA2: 0 | DB2: 0 | DC2: 0 | DD2: 0 | DE2: 0 | DF2: 0 | DG2: 0 | DH2: 0 | DI2: 0 | DJ2: 0 | DK2: 0 | DL2: 0 | DM2: 0 | DN2: 0 | DO2: 0 | DP2: 0 | DQ2: 0 | DR2: 0 | DS2: 0 | DT2: 0 | DU2: 0 | DV2: 0 | DW2: 0 | DX2: 0 | DY2: 0 | DZ2: 0 | EA2: 0 | EB2: 0 | EC2: 0 | ED2: 0 | EE2: 0 | EF2: 0 | EG2: 0 | EH2: 0 | EI2: 0 | EJ2: 0 | EK2: 0 | EL2: 0 | EM2: 0 | EN2: 0 | EO2: 0 | EP2: 0 | EQ2: 0 | ER2: 0 | ES2: 0 | ET2: 0 | EU2: 0 | EV2: 0 | EW2: 0 | EX2: 0 | EY2: 0 | EZ2: 0 | FA2: 0 | FB2: 0 | FC2: 0 | FD2: 0 | FE2: 0 | FF2: 0 | FG2: 0 | FH2: 0 | FI2: 0 | FJ2: 0 | FK2: 0 | FL2: 0 | FM2: 0 | FN2: 0 | FO2: 0 | FP2: 0 | FQ2: 0 | FR2: 0 | FS2: 0 | FT2: 0 | FU2: 0 | FV2: 0 | FW2: 0 | FX2: 0 | FY2: 0 | FZ2: 0 | GA2: 0 | GB2: 0 | GC2: 0 | GD2: 0 | GE2: 0 | GF2: 0 | GG2: 0 | GH2: 0 | GI2: 0 | GJ2: 0 | GK2: 0 | GL2: 0 | GM2: 0 | GN2: 0 | GO2: 0 | GP2: 0 | GQ2: 0 | GR2: 0 | GS2: 0 | GT2: 0 | GU2: 0 | GV2: 0 | GW2: 0 | GX2: 0 | GY2: 0 | GZ2: 0 | HA2: 0 | HB2: 0 | HC2: 0 | HD2: 0 | HE2: 0 | HF2: 0 | HG2: 0 | HH2: 0 | HI2: 0 | HJ2: 0 | HK2: 0 | HL2: 0 | HM2: 0 | HN2: 0 | HO2: 0 | HP2: 0 | HQ2: 0 | HR2: 0 | HS2: 0 | HT2: 0 | HU2: 0 | HV2: 0 | HW2: 0 | HX2: 0 | HY2: 0 | HZ2: 0 | IA2: 0 | IB2: 0 | IC2: 0 | ID2: 0 | IE2: 0 | IF2: 0 | IG2: 0 | IH2: 0 | II2: 0 | IJ2: 0 | IK2: 0 | IL2: 0 | IM2: 0 | IN2: 0 | IO2: 0 | IP2: 0 | IQ2: 0 | IR2: 0 | IS2: 0 | IT2: 0 | IU2: 0 | IV2: 0 | IW2: 0 | IX2: 0 | IY2: 0 | IZ2: 0 | JA2: 0 | JB2: 0 | JC2: 0 | JD2: 0 | JE2: 0 | JF2: 0 | JG2: 0 | JH2: 0 | JI2: 0 | JJ2: 0 | JK2: 0 | JL2: 0 | JM2: 0 | JN2: 0 | JO2: 0 | JP2: 0 | JQ2: 0 | JR2: 0 | JS2: 0 | JT2: 0 | JU2: 0 | JV2: 0 | JW2: 0 | JX2: 0 | JY2: 0 | JZ2: 0 | KA2: 0 | KB2: 0 | KC2: 0 | KD2: 0 | KE2: 0 | KF2: 0 | KG2: 0 | KH2: 0 | KI2: 0 | KJ2: 0 | KK2: 0 | KL2: 0 | KM2: 0 | KN2: 0 | KO2: 0 | KP2: 0 | KQ2: 0 | KR2: 0 | KS2: 0 | KT2: 0 | KU2: 0 | KV2: 0 | KW2: 0 | KX2: 0 | KY2: 0 | KZ2: 0 | LA2: 0 | LB2: 0 | LC2: 0 | LD2: 0 | LE2: 0 | LF2: 0 | LG2: 0 | LH2: 0 | LI2: 0 | LJ2: 0 | LK2: 0 | LL2: 0 | LM2: 0 | LN2: 0 | LO2: 0 | LP2: 0 | LQ2: 0 | LR2: 0 | LS2: 0 | LT2: 0 | LU2: 0 | LV2: 0 | LW2: 0 | LX2: 0 | LY2: 0 | LZ2: 0 | MA2: 0 | MB2: 0 | MC2: 0 | MD2: 0 | ME2: 0 | MF2: 0 | MG2: 0 | MH2: 0 | MI2: 0 | MJ2: 0 | MK2: 0 | ML2: 0 | MM2: 0 | MN2: 0 | MO2: 0 | MP2: 0 | MQ2: 0 | MR2: 0 | MS2: 0 | MT2: 0 | MU2: 0 | MV2: 0 | MW2: 0 | MX2: 0 | MY2: 0 | MZ2: 0 | NA2: 0 | NB2: 0 | NC2: 825
A3: Occupancy | B3: 0.37037037 | C3: 0.18518519 | D3: 0.22222222 | E3: 0.074074074 | F3: 0 | G3: 0 | H3: 0 | I3: 0 | J3: 0.074074074 | K3: 0.074074074 | L3: 0 | M3: 0 | N3: 0 | O3: 0.037037037 | P3: 0 | Q3: 0.037037037 | R3: 0.037037037 | S3: 0 | T3: 0 | U3: 0 | V3: 0 | W3: 0 | X3: 0 | Y3: 0.074074074 | Z3: 0 | AA3: 0 | AB3: 0.037037037 | AC3: 0.037037037 | AD3: 0.037037037 | AE3: 0.074074074 | AF3: 0.11111111 | AG3: 0.074074074 | AH3: 0.074074074 | AI3: 0.074074074 | AJ3: 0.037037037 | AK3: 0 | AL3: 0.074074074 | AM3: 0.074074074 | AN3: 0.11111111 | AO3: 0.11111111 | AP3: 0.14814815 | AQ3: 0.17857143 | AR3: 0.071428571 | AS3: 0.25 | AT3: 0.85714286 | AU3: 0.035714286 | AV3: 0.035714286 | AW3: 0 | AX3: 0 | AY3: 0.071428571 | AZ3: 0.10714286 | BA3: 0.035714286 | BB3: 0 | BC3: 0 | BD3: 0.035714286 | BE3: 0.035714286 | BF3: 0 | BG3: 0.035714286 | BH3: 0.17857143 | BI3: 0 | BJ3: 0 | BK3: 0 | BL3: 0 | BM3: 0 | BN3: 0.10714286 | BO3: 0.28571429 | BP3: 0.035714286 | BQ3: 0.035714286 | BR3: 0 | BS3: 0 | BT3: 0 | BU3: 0.071428571 | BV3: 0.25 | BW3: 0 | BX3: 0 | BY3: 0 | BZ3: 0 | CA3: 0 | CB3: 0.071428571 | CC3: 0.25 | CD3: 0 | CE3: 0 | CF3: 0 | CG3: 0.035714286 | CH3: 0.035714286 | CI3: 0.071428571 | CJ3: 0.10714286 | CK3: 0.035714286 | CL3: 0.071428571 | CM3: 0.035714286 | CN3: 0.071428571 | CO3: 0.21428571 | CP3: 0.57142857 | CQ3: 0.75 | CR3: 0.21428571 | CS3: 0.14285714 | CT3: 0.28571429 | CU3: 0.25 | CV3: 0.35714286 | CW3: 0.39285714 | CX3: 0.89285714 | CY3: 0.21428571 | CZ3: 0.10714286 | DA3: 0.14285714 | DB3: 0.32142857 | DC3: 0.85714286 | DD3: 0.89285714 | DE3: 0.89285714 | DF3: 0.53571429 | DG3: 0.57142857 | DH3: 0.64285714 | DI3: 0.5 | DJ3: 0.64285714 | DK3: 0.78571429 | DL3: 0.78571429 | DM3: 0.10714286 | DN3: 0.28571429 | DO3: 0.32142857 | DP3: 0.35714286 | DQ3: 0.32142857 | DR3: 0.89285714 | DS3: 0.85714286 | DT3: 0.035714286 | DU3: 0 | DV3: 0 | DW3: 0 | DX3: 0 | DY3: 0.035714286 | DZ3: 0.53571429 | EA3: 0.035714286 | EB3: 0.035714286 | EC3: 0.035714286 | ED3: 0.071428571 | EE3: 0.75 | EF3: 0.89285714 | EG3: 0.78571429 | EH3: 0.035714286 | EI3: 0.10714286 | EJ3: 0.10714286 | EK3: 0.071428571 | EL3: 0.10714286 | EM3: 0.17857143 | EN3: 0.75 | EO3: 0.10714286 | EP3: 0 | EQ3: 0 | ER3: 0 | ES3: 0 | ET3: 0 | EU3: 0.53571429 | EV3: 0 | EW3: 0.035714286 | EX3: 0 | EY3: 0 | EZ3: 0.32142857 | FA3: 0.5 | FB3: 0.57142857 | FC3: 0.035714286 | FD3: 0.035714286 | FE3: 0.035714286 | FF3: 0.035714286 | FG3: 0 | FH3: 0.071428571 | FI3: 0.46428571 | FJ3: 0 | FK3: 0 | FL3: 0 | FM3: 0 | FN3: 0 | FO3: 0.071428571 | FP3: 0.78571429 | FQ3: 0 | FR3: 0 | FS3: 0 | FT3: 0 | FU3: 0 | FV3: 0.35714286 | FW3: 0.75 | FX3: 0.035714286 | FY3: 0.071428571 | FZ3: 0.071428571 | GA3: 0.066666667 | GB3: 0 | GC3: 0.066666667 | GD3: 0.56666667 | GE3: 0.13333333 | GF3: 0.033333333 | GG3: 0.033333333 | GH3: 0.033333333 | GI3: 0.033333333 | GJ3: 0.066666667 | GK3: 0.16666667 | GL3: 0 | GM3: 0 | GN3: 0 | GO3: 0 | GP3: 0 | GQ3: 0.13333333 | GR3: 0.13333333 | GS3: 0.1 | GT3: 0 | GU3: 0.066666667 | GV3: 0 | GW3: 0 | GX3: 0.033333333 | GY3: 0.3 | GZ3: 0.13333333 | HA3: 0.033333333 | HB3: 0.033333333 | HC3: 0.066666667 | HD3: 0.1 | HE3: 0.3 | HF3: 0.26666667 | HG3: 0.066666667 | HH3: 0 | HI3: 0 | HJ3: 0 | HK3: 0 | HL3: 0.13333333 | HM3: 0.16666667 | HN3: 0 | HO3: 0.033333333 | HP3: 0.066666667 | HQ3: 0.066666667 | HR3: 0.066666667 | HS3: 0.066666667 | HT3: 0.36666667 | HU3: 0.066666667 | HV3: 0.033333333 | HW3: 0 | HX3: 0 | HY3: 0.16666667 | HZ3: 0.73333333 | IA3: 0.83333333 | IB3: 0.13333333 | IC3: 0 | ID3: 0 | IE3: 0 | IF3: 0 | IG3: 0 | IH3: 0.033333333 | II3: 0 | IJ3: 0 | IK3: 0 | IL3: 0 | IM3: 0 | IN3: 0 | IO3: 0.43333333 | IP3: 0 | IQ3: 0 | IR3: 0 | IS3: 0 | IT3: 0 | IU3: 0 | IV3: 0 | IW3: 0 | IX3: 0 | IY3: 0 | IZ3: 0 | JA3: 0 | JB3: 0 | JC3: 0 | JD3: 0 | JE3: 0 | JF3: 0 | JG3: 0 | JH3: 0 | JI3: 0 | JJ3: 0 | JK3: 0 | JL3: 0 | JM3: 0 | JN3: 0 | JO3: 0 | JP3: 0 | JQ3: 0.066666667 | JR3: 0 | JS3: 0 | JT3: 0 | JU3: 0 | JV3: 0 | JW3: 0 | JX3: 0 | JY3: 0 | JZ3: 0 | KA3: 0 | KB3: 0 | KC3: 0 | KD3: 0.033333333 | KE3: 0.033333333 | KF3: 0 | KG3: 0 | KH3: 0 | KI3: 0 | KJ3: 0 | KK3: 0 | KL3: 0 | KM3: 0 | KN3: 0 | KO3: 0 | KP3: 0 | KQ3: 0 | KR3: 0 | KS3: 0 | KT3: 0 | KU3: 0 | KV3: 0 | KW3: 0 | KX3: 0 | KY3: 0 | KZ3: 0 | LA3: 0 | LB3: 0 | LC3: 0 | LD3: 0 | LE3: 0 | LF3: 0 | LG3: 0 | LH3: 0 | LI3: 0 | LJ3: 0 | LK3: 0 | LL3: 0 | LM3: 0 | LN3: 0 | LO3: 0 | LP3: 0 | LQ3: 0 | LR3: 0 | LS3: 0 | LT3: 0 | LU3: 0 | LV3: 0 | LW3: 0 | LX3: 0 | LY3: 0 | LZ3: 0 | MA3: 0 | MB3: 0 | MC3: 0 | MD3: 0 | ME3: 0 | MF3: 0 | MG3: 0 | MH3: 0 | MI3: 0 | MJ3: 0 | MK3: 0 | ML3: 0 | MM3: 0 | MN3: 0 | MO3: 0 | MP3: 0 | MQ3: 0 | MR3: 0 | MS3: 0 | MT3: 0 | MU3: 0 | MV3: 0 | MW3: 0 | MX3: 0 | MY3: 0 | MZ3: 0 | NA3: 0 | NB3: 0 | NC3: 0.098795866
A4: Available | B4: 27 | C4: 27 | D4: 27 | E4: 27 | F4: 27 | G4: 27 | H4: 27 | I4: 27 | J4: 27 | K4: 27 | L4: 27 | M4: 27 | N4: 27 | O4: 27 | P4: 27 | Q4: 27 | R4: 27 | S4: 27 | T4: 27 | U4: 27 | V4: 27 | W4: 27 | X4: 27 | Y4: 27 | Z4: 27 | AA4: 27 | AB4: 27 | AC4: 27 | AD4: 27 | AE4: 27 | AF4: 27 | AG4: 27 | AH4: 27 | AI4: 27 | AJ4: 27 | AK4: 27 | AL4: 27 | AM4: 27 | AN4: 27 | AO4: 27 | AP4: 27 | AQ4: 28 | AR4: 28 | AS4: 28 | AT4: 28 | AU4: 28 | AV4: 28 | AW4: 28 | AX4: 28 | AY4: 28 | AZ4: 28 | BA4: 28 | BB4: 28 | BC4: 28 | BD4: 28 | BE4: 28 | BF4: 28 | BG4: 28 | BH4: 28 | BI4: 28 | BJ4: 28 | BK4: 28 | BL4: 28 | BM4: 28 | BN4: 28 | BO4: 28 | BP4: 28 | BQ4: 28 | BR4: 28 | BS4: 28 | BT4: 28 | BU4: 28 | BV4: 28 | BW4: 28 | BX4: 28 | BY4: 28 | BZ4: 28 | CA4: 28 | CB4: 28 | CC4: 28 | CD4: 28 | CE4: 28 | CF4: 28 | CG4: 28 | CH4: 28 | CI4: 28 | CJ4: 28 | CK4: 28 | CL4: 28 | CM4: 28 | CN4: 28 | CO4: 28 | CP4: 28 | CQ4: 28 | CR4: 28 | CS4: 28 | CT4: 28 | CU4: 28 | CV4: 28 | CW4: 28 | CX4: 28 | CY4: 28 | CZ4: 28 | DA4: 28 | DB4: 28 | DC4: 28 | DD4: 28 | DE4: 28 | DF4: 28 | DG4: 28 | DH4: 28 | DI4: 28 | DJ4: 28 | DK4: 28 | DL4: 28 | DM4: 28 | DN4: 28 | DO4: 28 | DP4: 28 | DQ4: 28 | DR4: 28 | DS4: 28 | DT4: 28 | DU4: 28 | DV4: 28 | DW4: 28 | DX4: 28 | DY4: 28 | DZ4: 28 | EA4: 28 | EB4: 28 | EC4: 28 | ED4: 28 | EE4: 28 | EF4: 28 | EG4: 28 | EH4: 28 | EI4: 28 | EJ4: 28 | EK4: 28 | EL4: 28 | EM4: 28 | EN4: 28 | EO4: 28 | EP4: 28 | EQ4: 28 | ER4: 28 | ES4: 28 | ET4: 28 | EU4: 28 | EV4: 28 | EW4: 28 | EX4: 28 | EY4: 28 | EZ4: 28 | FA4: 28 | FB4: 28 | FC4: 28 | FD4: 28 | FE4: 28 | FF4: 28 | FG4: 28 | FH4: 28 | FI4: 28 | FJ4: 28 | FK4: 28 | FL4: 28 | FM4: 28 | FN4: 28 | FO4: 28 | FP4: 28 | FQ4: 28 | FR4: 28 | FS4: 28 | FT4: 28 | FU4: 28 | FV4: 28 | FW4: 28 | FX4: 28 | FY4: 28 | FZ4: 28 | GA4: 30 | GB4: 30 | GC4: 30 | GD4: 30 | GE4: 30 | GF4: 30 | GG4: 30 | GH4: 30 | GI4: 30 | GJ4: 30 | GK4: 30 | GL4: 30 | GM4: 30 | GN4: 30 | GO4: 30 | GP4: 30 | GQ4: 30 | GR4: 30 | GS4: 30 | GT4: 30 | GU4: 30 | GV4: 30 | GW4: 30 | GX4: 30 | GY4: 30 | GZ4: 30 | HA4: 30 | HB4: 30 | HC4: 30 | HD4: 30 | HE4: 30 | HF4: 30 | HG4: 30 | HH4: 30 | HI4: 30 | HJ4: 30 | HK4: 30 | HL4: 30 | HM4: 30 | HN4: 30 | HO4: 30 | HP4: 30 | HQ4: 30 | HR4: 30 | HS4: 30 | HT4: 30 | HU4: 30 | HV4: 30 | HW4: 30 | HX4: 30 | HY4: 30 | HZ4: 30 | IA4: 30 | IB4: 30 | IC4: 30 | ID4: 30 | IE4: 30 | IF4: 30 | IG4: 30 | IH4: 30 | II4: 30 | IJ4: 30 | IK4: 30 | IL4: 30 | IM4: 30 | IN4: 30 | IO4: 30 | IP4: 30 | IQ4: 30 | IR4: 30 | IS4: 30 | IT4: 30 | IU4: 30 | IV4: 30 | IW4: 30 | IX4: 30 | IY4: 30 | IZ4: 30 | JA4: 30 | JB4: 30 | JC4: 30 | JD4: 30 | JE4: 30 | JF4: 30 | JG4: 30 | JH4: 30 | JI4: 30 | JJ4: 30 | JK4: 30 | JL4: 30 | JM4: 30 | JN4: 30 | JO4: 30 | JP4: 30 | JQ4: 30 | JR4: 30 | JS4: 30 | JT4: 30 | JU4: 30 | JV4: 30 | JW4: 30 | JX4: 30 | JY4: 30 | JZ4: 30 | KA4: 30 | KB4: 30 | KC4: 30 | KD4: 30 | KE4: 30 | KF4: 30 | KG4: 30 | KH4: 30 | KI4: 30 | KJ4: 30 | KK4: 30 | KL4: 30 | KM4: 30 | KN4: 30 | KO4: 30 | KP4: 30 | KQ4: 30 | KR4: 30 | KS4: 30 | KT4: 30 | KU4: 30 | KV4: 30 | KW4: 30 | KX4: 30 | KY4: 30 | KZ4: 30 | LA4: 30 | LB4: 30 | LC4: 30 | LD4: 30 | LE4: 30 | LF4: 30 | LG4: 30 | LH4: 30 | LI4: 30 | LJ4: 30 | LK4: 30 | LL4: 30 | LM4: 30 | LN4: 30 | LO4: 30 | LP4: 30 | LQ4: 30 | LR4: 30 | LS4: 30 | LT4: 30 | LU4: 30 | LV4: 30 | LW4: 30 | LX4: 30 | LY4: 30 | LZ4: 30 | MA4: 30 | MB4: 30 | MC4: 30 | MD4: 30 | ME4: 30 | MF4: 30 | MG4: 30 | MH4: 30 | MI4: 30 | MJ4: 30 | MK4: 30 | ML4: 30 | MM4: 30 | MN4: 30 | MO4: 30 | MP4: 30 | MQ4: 30 | MR4: 30 | MS4: 30 | MT4: 30 | MU4: 30 | MV4: 30 | MW4: 30 | MX4: 30 | MY4: 30 | MZ4: 30 | NA4: 30 | NB4: 30 | NC4: 10547
A5: Occupied | B5: 10 | C5: 5 | D5: 6 | E5: 2 | F5: 0 | G5: 0 | H5: 0 | I5: 0 | J5: 2 | K5: 2 | L5: 0 | M5: 0 | N5: 0 | O5: 1 | P5: 0 | Q5: 1 | R5: 1 | S5: 0 | T5: 0 | U5: 0 | V5: 0 | W5: 0 | X5: 0 | Y5: 2 | Z5: 0 | AA5: 0 | AB5: 1 | AC5: 1 | AD5: 1 | AE5: 2 | AF5: 3 | AG5: 2 | AH5: 2 | AI5: 2 | AJ5: 1 | AK5: 0 | AL5: 2 | AM5: 2 | AN5: 3 | AO5: 3 | AP5: 4 | AQ5: 5 | AR5: 2 | AS5: 7 | AT5: 24 | AU5: 1 | AV5: 1 | AW5: 0 | AX5: 0 | AY5: 2 | AZ5: 3 | BA5: 1 | BB5: 0 | BC5: 0 | BD5: 1 | BE5: 1 | BF5: 0 | BG5: 1 | BH5: 5 | BI5: 0 | BJ5: 0 | BK5: 0 | BL5: 0 | BM5: 0 | BN5: 3 | BO5: 8 | BP5: 1 | BQ5: 1 | BR5: 0 | BS5: 0 | BT5: 0 | BU5: 2 | BV5: 7 | BW5: 0 | BX5: 0 | BY5: 0 | BZ5: 0 | CA5: 0 | CB5: 2 | CC5: 7 | CD5: 0 | CE5: 0 | CF5: 0 | CG5: 1 | CH5: 1 | CI5: 2 | CJ5: 3 | CK5: 1 | CL5: 2 | CM5: 1 | CN5: 2 | CO5: 6 | CP5: 16 | CQ5: 21 | CR5: 6 | CS5: 4 | CT5: 8 | CU5: 7 | CV5: 10 | CW5: 11 | CX5: 25 | CY5: 6 | CZ5: 3 | DA5: 4 | DB5: 9 | DC5: 24 | DD5: 25 | DE5: 25 | DF5: 15 | DG5: 16 | DH5: 18 | DI5: 14 | DJ5: 18 | DK5: 22 | DL5: 22 | DM5: 3 | DN5: 8 | DO5: 9 | DP5: 10 | DQ5: 9 | DR5: 25 | DS5: 24 | DT5: 1 | DU5: 0 | DV5: 0 | DW5: 0 | DX5: 0 | DY5: 1 | DZ5: 15 | EA5: 1 | EB5: 1 | EC5: 1 | ED5: 2 | EE5: 21 | EF5: 25 | EG5: 22 | EH5: 1 | EI5: 3 | EJ5: 3 | EK5: 2 | EL5: 3 | EM5: 5 | EN5: 21 | EO5: 3 | EP5: 0 | EQ5: 0 | ER5: 0 | ES5: 0 | ET5: 0 | EU5: 15 | EV5: 0 | EW5: 1 | EX5: 0 | EY5: 0 | EZ5: 9 | FA5: 14 | FB5: 16 | FC5: 1 | FD5: 1 | FE5: 1 | FF5: 1 | FG5: 0 | FH5: 2 | FI5: 13 | FJ5: 0 | FK5: 0 | FL5: 0 | FM5: 0 | FN5: 0 | FO5: 2 | FP5: 22 | FQ5: 0 | FR5: 0 | FS5: 0 | FT5: 0 | FU5: 0 | FV5: 10 | FW5: 21 | FX5: 1 | FY5: 2 | FZ5: 2 | GA5: 2 | GB5: 0 | GC5: 2 | GD5: 17 | GE5: 4 | GF5: 1 | GG5: 1 | GH5: 1 | GI5: 1 | GJ5: 2 | GK5: 5 | GL5: 0 | GM5: 0 | GN5: 0 | GO5: 0 | GP5: 0 | GQ5: 4 | GR5: 4 | GS5: 3 | GT5: 0 | GU5: 2 | GV5: 0 | GW5: 0 | GX5: 1 | GY5: 9 | GZ5: 4 | HA5: 1 | HB5: 1 | HC5: 2 | HD5: 3 | HE5: 9 | HF5: 8 | HG5: 2 | HH5: 0 | HI5: 0 | HJ5: 0 | HK5: 0 | HL5: 4 | HM5: 5 | HN5: 0 | HO5: 1 | HP5: 2 | HQ5: 2 | HR5: 2 | HS5: 2 | HT5: 11 | HU5: 2 | HV5: 1 | HW5: 0 | HX5: 0 | HY5: 5 | HZ5: 22 | IA5: 25 | IB5: 4 | IC5: 0 | ID5: 0 | IE5: 0 | IF5: 0 | IG5: 0 | IH5: 1 | II5: 0 | IJ5: 0 | IK5: 0 | IL5: 0 | IM5: 0 | IN5: 0 | IO5: 13 | IP5: 0 | IQ5: 0 | IR5: 0 | IS5: 0 | IT5: 0 | IU5: 0 | IV5: 0 | IW5: 0 | IX5: 0 | IY5: 0 | IZ5: 0 | JA5: 0 | JB5: 0 | JC5: 0 | JD5: 0 | JE5: 0 | JF5: 0 | JG5: 0 | JH5: 0 | JI5: 0 | JJ5: 0 | JK5: 0 | JL5: 0 | JM5: 0 | JN5: 0 | JO5: 0 | JP5: 0 | JQ5: 2 | JR5: 0 | JS5: 0 | JT5: 0 | JU5: 0 | JV5: 0 | JW5: 0 | JX5: 0 | JY5: 0 | JZ5: 0 | KA5: 0 | KB5: 0 | KC5: 0 | KD5: 1 | KE5: 1 | KF5: 0 | KG5: 0 | KH5: 0 | KI5: 0 | KJ5: 0 | KK5: 0 | KL5: 0 | KM5: 0 | KN5: 0 | KO5: 0 | KP5: 0 | KQ5: 0 | KR5: 0 | KS5: 0 | KT5: 0 | KU5: 0 | KV5: 0 | KW5: 0 | KX5: 0 | KY5: 0 | KZ5: 0 | LA5: 0 | LB5: 0 | LC5: 0 | LD5: 0 | LE5: 0 | LF5: 0 | LG5: 0 | LH5: 0 | LI5: 0 | LJ5: 0 | LK5: 0 | LL5: 0 | LM5: 0 | LN5: 0 | LO5: 0 | LP5: 0 | LQ5: 0 | LR5: 0 | LS5: 0 | LT5: 0 | LU5: 0 | LV5: 0 | LW5: 0 | LX5: 0 | LY5: 0 | LZ5: 0 | MA5: 0 | MB5: 0 | MC5: 0 | MD5: 0 | ME5: 0 | MF5: 0 | MG5: 0 | MH5: 0 | MI5: 0 | MJ5: 0 | MK5: 0 | ML5: 0 | MM5: 0 | MN5: 0 | MO5: 0 | MP5: 0 | MQ5: 0 | MR5: 0 | MS5: 0 | MT5: 0 | MU5: 0 | MV5: 0 | MW5: 0 | MX5: 0 | MY5: 0 | MZ5: 0 | NA5: 0 | NB5: 0 | NC5: 1042
A6: Revenue (nights) | B6: 914.5 | C6: 436 | D6: 515 | E6: 168 | F6: 0 | G6: 0 | H6: 0 | I6: 0 | J6: 177.11 | K6: 186.9 | L6: 0 | M6: 0 | N6: 0 | O6: 88.11 | P6: 0 | Q6: 88.11 | R6: 88.11 | S6: 0 | T6: 0 | U6: 0 | V6: 0 | W6: 0 | X6: 0 | Y6: 168.21 | Z6: 0 | AA6: 0 | AB6: 58 | AC6: 58 | AD6: 58 | AE6: 117.23 | AF6: 205.34 | AG6: 117.23 | AH6: 129.1 | AI6: 129.1 | AJ6: 71.1 | AK6: 0 | AL6: 159.21 | AM6: 158 | AN6: 283.91 | AO6: 283.91 | AP6: 370.81 | AQ6: 457.71 | AR6: 173.8 | AS6: 576.57 | AT6: 1965.63 | AU6: 65.91 | AV6: 65.91 | AW6: 0 | AX6: 0 | AY6: 176.22 | AZ6: 254.43 | BA6: 97.9 | BB6: 0 | BC6: 0 | BD6: 88.11 | BE6: 97.9 | BF6: 0 | BG6: 88.11 | BH6: 447.67 | BI6: 0 | BJ6: 0 | BK6: 0 | BL6: 0 | BM6: 0 | BN6: 249.2 | BO6: 729.8 | BP6: 75.65 | BQ6: 75.65 | BR6: 0 | BS6: 0 | BT6: 0 | BU6: 132.55 | BV6: 591.48 | BW6: 0 | BX6: 0 | BY6: 0 | BZ6: 0 | CA6: 0 | CB6: 226.1 | CC6: 793 | CD6: 0 | CE6: 0 | CF6: 0 | CG6: 90.82 | CH6: 90.82 | CI6: 218.15 | CJ6: 366.52 | CK6: 89.69 | CL6: 185.52 | CM6: 89.69 | CN6: 197.6 | CO6: 619.43 | CP6: 1846.06 | CQ6: 2337.08 | CR6: 601.57 | CS6: 366.03 | CT6: 801.87 | CU6: 718.61 | CV6: 1021.64 | CW6: 1202.51 | CX6: 2789.99 | CY6: 607.49 | CZ6: 247.41 | DA6: 452.93 | DB6: 930.63 | DC6: 2942.78 | DD6: 2689.22 | DE6: 2608.32 | DF6: 1557.01 | DG6: 1657.14 | DH6: 1819.7 | DI6: 1450.09 | DJ6: 1856.31 | DK6: 2528.71 | DL6: 2470.17 | DM6: 265.29 | DN6: 758.59 | DO6: 866.5 | DP6: 959.12 | DQ6: 951.34 | DR6: 2869.02 | DS6: 2782.53 | DT6: 81.73 | DU6: 0 | DV6: 0 | DW6: 0 | DX6: 0 | DY6: 117.81 | DZ6: 1771.53 | EA6: 107.91 | EB6: 107.91 | EC6: 107.91 | ED6: 215.82 | EE6: 2187.25 | EF6: 2815.21 | EG6: 2507.63 | EH6: 77.86 | EI6: 293.68 | EJ6: 293.68 | EK6: 215.82 | EL6: 323.73 | EM6: 550.82 | EN6: 3043.9 | EO6: 313.92 | EP6: 0 | EQ6: 0 | ER6: 0 | ES6: 0 | ET6: 0 | EU6: 1930.09 | EV6: 0 | EW6: 98.1 | EX6: 0 | EY6: 0 | EZ6: 896.84 | FA6: 1491.06 | FB6: 1754 | FC6: 109 | FD6: 109 | FE6: 109 | FF6: 109 | FG6: 0 | FH6: 216.1 | FI6: 1418.1 | FJ6: 0 | FK6: 0 | FL6: 0 | FM6: 0 | FN6: 0 | FO6: 249.81 | FP6: 2784.19 | FQ6: 0 | FR6: 0 | FS6: 0 | FT6: 0 | FU6: 0 | FV6: 1227.46 | FW6: 2537.96 | FX6: 109 | FY6: 186.86 | FZ6: 186.86 | GA6: 168.24 | GB6: 0 | GC6: 225.72 | GD6: 1964.97 | GE6: 411.84 | GF6: 98.1 | GG6: 98.1 | GH6: 98.1 | GI6: 98.1 | GJ6: 205.2 | GK6: 579.15 | GL6: 0 | GM6: 0 | GN6: 0 | GO6: 0 | GP6: 0 | GQ6: 714 | GR6: 440.73 | GS6: 313.92 | GT6: 0 | GU6: 186.12 | GV6: 0 | GW6: 0 | GX6: 117.81 | GY6: 1021.02 | GZ6: 411.84 | HA6: 107.91 | HB6: 107.91 | HC6: 205.92 | HD6: 294.03 | HE6: 1130.22 | HF6: 962.33 | HG6: 205.92 | HH6: 0 | HI6: 0 | HJ6: 0 | HK6: 0 | HL6: 471.24 | HM6: 589.05 | HN6: 0 | HO6: 109 | HP6: 228.9 | HQ6: 228.9 | HR6: 228.9 | HS6: 249.9 | HT6: 1341.71 | HU6: 195.34 | HV6: 97.33 | HW6: 0 | HX6: 0 | HY6: 612.7 | HZ6: 2853 | IA6: 3202.1 | IB6: 515.9 | IC6: 0 | ID6: 0 | IE6: 0 | IF6: 0 | IG6: 0 | IH6: 130.9 | II6: 0 | IJ6: 0 | IK6: 0 | IL6: 0 | IM6: 0 | IN6: 0 | IO6: 1402.83 | IP6: 0 | IQ6: 0 | IR6: 0 | IS6: 0 | IT6: 0 | IU6: 0 | IV6: 0 | IW6: 0 | IX6: 0 | IY6: 0 | IZ6: 0 | JA6: 0 | JB6: 0 | JC6: 0 | JD6: 0 | JE6: 0 | JF6: 0 | JG6: 0 | JH6: 0 | JI6: 0 | JJ6: 0 | JK6: 0 | JL6: 0 | JM6: 0 | JN6: 0 | JO6: 0 | JP6: 0 | JQ6: 176.22 | JR6: 0 | JS6: 0 | JT6: 0 | JU6: 0 | JV6: 0 | JW6: 0 | JX6: 0 | JY6: 0 | JZ6: 0 | KA6: 0 | KB6: 0 | KC6: 0 | KD6: 78.21 | KE6: 78.21 | KF6: 0 | KG6: 0 | KH6: 0 | KI6: 0 | KJ6: 0 | KK6: 0 | KL6: 0 | KM6: 0 | KN6: 0 | KO6: 0 | KP6: 0 | KQ6: 0 | KR6: 0 | KS6: 0 | KT6: 0 | KU6: 0 | KV6: 0 | KW6: 0 | KX6: 0 | KY6: 0 | KZ6: 0 | LA6: 0 | LB6: 0 | LC6: 0 | LD6: 0 | LE6: 0 | LF6: 0 | LG6: 0 | LH6: 0 | LI6: 0 | LJ6: 0 | LK6: 0 | LL6: 0 | LM6: 0 | LN6: 0 | LO6: 0 | LP6: 0 | LQ6: 0 | LR6: 0 | LS6: 0 | LT6: 0 | LU6: 0 | LV6: 0 | LW6: 0 | LX6: 0 | LY6: 0 | LZ6: 0 | MA6: 0 | MB6: 0 | MC6: 0 | MD6: 0 | ME6: 0 | MF6: 0 | MG6: 0 | MH6: 0 | MI6: 0 | MJ6: 0 | MK6: 0 | ML6: 0 | MM6: 0 | MN6: 0 | MO6: 0 | MP6: 0 | MQ6: 0 | MR6: 0 | MS6: 0 | MT6: 0 | MU6: 0 | MV6: 0 | MW6: 0 | MX6: 0 | MY6: 0 | MZ6: 0 | NA6: 0 | NB6: 0 | NC6: 112976.28
A7: Average rate (nightly) | B7: 91.45 | C7: 87.2 | D7: 85.83 | E7: 84 | F7: 0 | G7: 0 | H7: 0 | I7: 0 | J7: 88.56 | K7: 93.45 | L7: 0 | M7: 0 | N7: 0 | O7: 88.11 | P7: 0 | Q7: 88.11 | R7: 88.11 | S7: 0 | T7: 0 | U7: 0 | V7: 0 | W7: 0 | X7: 0 | Y7: 84.11 | Z7: 0 | AA7: 0 | AB7: 58 | AC7: 58 | AD7: 58 | AE7: 58.62 | AF7: 68.45 | AG7: 58.62 | AH7: 64.55 | AI7: 64.55 | AJ7: 71.1 | AK7: 0 | AL7: 79.61 | AM7: 79 | AN7: 94.64 | AO7: 94.64 | AP7: 92.7 | AQ7: 91.54 | AR7: 86.9 | AS7: 82.37 | AT7: 81.9 | AU7: 65.91 | AV7: 65.91 | AW7: 0 | AX7: 0 | AY7: 88.11 | AZ7: 84.81 | BA7: 97.9 | BB7: 0 | BC7: 0 | BD7: 88.11 | BE7: 97.9 | BF7: 0 | BG7: 88.11 | BH7: 89.53 | BI7: 0 | BJ7: 0 | BK7: 0 | BL7: 0 | BM7: 0 | BN7: 83.07 | BO7: 91.23 | BP7: 75.65 | BQ7: 75.65 | BR7: 0 | BS7: 0 | BT7: 0 | BU7: 66.28 | BV7: 84.5 | BW7: 0 | BX7: 0 | BY7: 0 | BZ7: 0 | CA7: 0 | CB7: 113.05 | CC7: 113.29 | CD7: 0 | CE7: 0 | CF7: 0 | CG7: 90.82 | CH7: 90.82 | CI7: 109.08 | CJ7: 122.17 | CK7: 89.69 | CL7: 92.76 | CM7: 89.69 | CN7: 98.8 | CO7: 103.24 | CP7: 115.38 | CQ7: 111.29 | CR7: 100.26 | CS7: 91.51 | CT7: 100.23 | CU7: 102.66 | CV7: 102.16 | CW7: 109.32 | CX7: 111.6 | CY7: 101.25 | CZ7: 82.47 | DA7: 113.23 | DB7: 103.4 | DC7: 122.62 | DD7: 107.57 | DE7: 104.33 | DF7: 103.8 | DG7: 103.57 | DH7: 101.09 | DI7: 103.58 | DJ7: 103.13 | DK7: 114.94 | DL7: 112.28 | DM7: 88.43 | DN7: 94.82 | DO7: 96.28 | DP7: 95.91 | DQ7: 105.7 | DR7: 114.76 | DS7: 115.94 | DT7: 81.73 | DU7: 0 | DV7: 0 | DW7: 0 | DX7: 0 | DY7: 117.81 | DZ7: 118.1 | EA7: 107.91 | EB7: 107.91 | EC7: 107.91 | ED7: 107.91 | EE7: 104.15 | EF7: 112.61 | EG7: 113.98 | EH7: 77.86 | EI7: 97.89 | EJ7: 97.89 | EK7: 107.91 | EL7: 107.91 | EM7: 110.16 | EN7: 144.95 | EO7: 104.64 | EP7: 0 | EQ7: 0 | ER7: 0 | ES7: 0 | ET7: 0 | EU7: 128.67 | EV7: 0 | EW7: 98.1 | EX7: 0 | EY7: 0 | EZ7: 99.65 | FA7: 106.5 | FB7: 109.63 | FC7: 109 | FD7: 109 | FE7: 109 | FF7: 109 | FG7: 0 | FH7: 108.05 | FI7: 109.08 | FJ7: 0 | FK7: 0 | FL7: 0 | FM7: 0 | FN7: 0 | FO7: 124.91 | FP7: 126.55 | FQ7: 0 | FR7: 0 | FS7: 0 | FT7: 0 | FU7: 0 | FV7: 122.75 | FW7: 120.86 | FX7: 109 | FY7: 93.43 | FZ7: 93.43 | GA7: 84.12 | GB7: 0 | GC7: 112.86 | GD7: 115.59 | GE7: 102.96 | GF7: 98.1 | GG7: 98.1 | GH7: 98.1 | GI7: 98.1 | GJ7: 102.6 | GK7: 115.83 | GL7: 0 | GM7: 0 | GN7: 0 | GO7: 0 | GP7: 0 | GQ7: 178.5 | GR7: 110.18 | GS7: 104.64 | GT7: 0 | GU7: 93.06 | GV7: 0 | GW7: 0 | GX7: 117.81 | GY7: 113.45 | GZ7: 102.96 | HA7: 107.91 | HB7: 107.91 | HC7: 102.96 | HD7: 98.01 | HE7: 125.58 | HF7: 120.29 | HG7: 102.96 | HH7: 0 | HI7: 0 | HJ7: 0 | HK7: 0 | HL7: 117.81 | HM7: 117.81 | HN7: 0 | HO7: 109 | HP7: 114.45 | HQ7: 114.45 | HR7: 114.45 | HS7: 124.95 | HT7: 121.97 | HU7: 97.67 | HV7: 97.33 | HW7: 0 | HX7: 0 | HY7: 122.54 | HZ7: 129.68 | IA7: 128.08 | IB7: 128.98 | IC7: 0 | ID7: 0 | IE7: 0 | IF7: 0 | IG7: 0 | IH7: 130.9 | II7: 0 | IJ7: 0 | IK7: 0 | IL7: 0 | IM7: 0 | IN7: 0 | IO7: 107.91 | IP7: 0 | IQ7: 0 | IR7: 0 | IS7: 0 | IT7: 0 | IU7: 0 | IV7: 0 | IW7: 0 | IX7: 0 | IY7: 0 | IZ7: 0 | JA7: 0 | JB7: 0 | JC7: 0 | JD7: 0 | JE7: 0 | JF7: 0 | JG7: 0 | JH7: 0 | JI7: 0 | JJ7: 0 | JK7: 0 | JL7: 0 | JM7: 0 | JN7: 0 | JO7: 0 | JP7: 0 | JQ7: 88.11 | JR7: 0 | JS7: 0 | JT7: 0 | JU7: 0 | JV7: 0 | JW7: 0 | JX7: 0 | JY7: 0 | JZ7: 0 | KA7: 0 | KB7: 0 | KC7: 0 | KD7: 78.21 | KE7: 78.21 | KF7: 0 | KG7: 0 | KH7: 0 | KI7: 0 | KJ7: 0 | KK7: 0 | KL7: 0 | KM7: 0 | KN7: 0 | KO7: 0 | KP7: 0 | KQ7: 0 | KR7: 0 | KS7: 0 | KT7: 0 | KU7: 0 | KV7: 0 | KW7: 0 | KX7: 0 | KY7: 0 | KZ7: 0 | LA7: 0 | LB7: 0 | LC7: 0 | LD7: 0 | LE7: 0 | LF7: 0 | LG7: 0 | LH7: 0 | LI7: 0 | LJ7: 0 | LK7: 0 | LL7: 0 | LM7: 0 | LN7: 0 | LO7: 0 | LP7: 0 | LQ7: 0 | LR7: 0 | LS7: 0 | LT7: 0 | LU7: 0 | LV7: 0 | LW7: 0 | LX7: 0 | LY7: 0 | LZ7: 0 | MA7: 0 | MB7: 0 | MC7: 0 | MD7: 0 | ME7: 0 | MF7: 0 | MG7: 0 | MH7: 0 | MI7: 0 | MJ7: 0 | MK7: 0 | ML7: 0 | MM7: 0 | MN7: 0 | MO7: 0 | MP7: 0 | MQ7: 0 | MR7: 0 | MS7: 0 | MT7: 0 | MU7: 0 | MV7: 0 | MW7: 0 | MX7: 0 | MY7: 0 | MZ7: 0 | NA7: 0 | NB7: 0 | NC7: 108.42
A8: Customers | B8: 18 | C8: 8 | D8: 9 | E8: 3 | F8: 0 | G8: 0 | H8: 0 | I8: 0 | J8: 3 | K8: 3 | L8: 0 | M8: 0 | N8: 0 | O8: 1 | P8: 0 | Q8: 1 | R8: 1 | S8: 0 | T8: 0 | U8: 0 | V8: 0 | W8: 0 | X8: 0 | Y8: 2 | Z8: 0 | AA8: 0 | AB8: 2 | AC8: 2 | AD8: 2 | AE8: 3 | AF8: 5 | AG8: 3 | AH8: 3 | AI8: 3 | AJ8: 1 | AK8: 0 | AL8: 3 | AM8: 2 | AN8: 3 | AO8: 3 | AP8: 4 | AQ8: 5 | AR8: 2 | AS8: 12 | AT8: 43 | AU8: 2 | AV8: 2 | AW8: 0 | AX8: 0 | AY8: 4 | AZ8: 5 | BA8: 2 | BB8: 0 | BC8: 0 | BD8: 2 | BE8: 2 | BF8: 0 | BG8: 2 | BH8: 10 | BI8: 0 | BJ8: 0 | BK8: 0 | BL8: 0 | BM8: 0 | BN8: 5 | BO8: 15 | BP8: 2 | BQ8: 2 | BR8: 0 | BS8: 0 | BT8: 0 | BU8: 3 | BV8: 12 | BW8: 0 | BX8: 0 | BY8: 0 | BZ8: 0 | CA8: 0 | CB8: 3 | CC8: 9 | CD8: 0 | CE8: 0 | CF8: 0 | CG8: 2 | CH8: 2 | CI8: 4 | CJ8: 6 | CK8: 2 | CL8: 3 | CM8: 2 | CN8: 4 | CO8: 12 | CP8: 31 | CQ8: 42 | CR8: 12 | CS8: 7 | CT8: 15 | CU8: 12 | CV8: 16 | CW8: 17 | CX8: 43 | CY8: 9 | CZ8: 3 | DA8: 7 | DB8: 14 | DC8: 34 | DD8: 45 | DE8: 45 | DF8: 23 | DG8: 23 | DH8: 24 | DI8: 20 | DJ8: 25 | DK8: 37 | DL8: 40 | DM8: 4 | DN8: 12 | DO8: 14 | DP8: 15 | DQ8: 17 | DR8: 46 | DS8: 45 | DT8: 2 | DU8: 0 | DV8: 0 | DW8: 0 | DX8: 0 | DY8: 2 | DZ8: 29 | EA8: 2 | EB8: 2 | EC8: 2 | ED8: 4 | EE8: 39 | EF8: 46 | EG8: 42 | EH8: 1 | EI8: 3 | EJ8: 3 | EK8: 2 | EL8: 4 | EM8: 8 | EN8: 42 | EO8: 6 | EP8: 0 | EQ8: 0 | ER8: 0 | ES8: 0 | ET8: 0 | EU8: 27 | EV8: 0 | EW8: 2 | EX8: 0 | EY8: 0 | EZ8: 18 | FA8: 27 | FB8: 32 | FC8: 2 | FD8: 1 | FE8: 1 | FF8: 2 | FG8: 0 | FH8: 4 | FI8: 24 | FJ8: 0 | FK8: 0 | FL8: 0 | FM8: 0 | FN8: 0 | FO8: 4 | FP8: 43 | FQ8: 0 | FR8: 0 | FS8: 0 | FT8: 0 | FU8: 0 | FV8: 20 | FW8: 40 | FX8: 1 | FY8: 2 | FZ8: 2 | GA8: 3 | GB8: 0 | GC8: 3 | GD8: 29 | GE8: 5 | GF8: 2 | GG8: 2 | GH8: 2 | GI8: 2 | GJ8: 3 | GK8: 9 | GL8: 0 | GM8: 0 | GN8: 0 | GO8: 0 | GP8: 0 | GQ8: 8 | GR8: 8 | GS8: 6 | GT8: 0 | GU8: 3 | GV8: 0 | GW8: 0 | GX8: 2 | GY8: 18 | GZ8: 8 | HA8: 2 | HB8: 2 | HC8: 3 | HD8: 3 | HE8: 14 | HF8: 14 | HG8: 2 | HH8: 0 | HI8: 0 | HJ8: 0 | HK8: 0 | HL8: 8 | HM8: 9 | HN8: 0 | HO8: 2 | HP8: 4 | HQ8: 4 | HR8: 4 | HS8: 4 | HT8: 21 | HU8: 3 | HV8: 2 | HW8: 0 | HX8: 0 | HY8: 9 | HZ8: 38 | IA8: 42 | IB8: 8 | IC8: 0 | ID8: 0 | IE8: 0 | IF8: 0 | IG8: 0 | IH8: 2 | II8: 0 | IJ8: 0 | IK8: 0 | IL8: 0 | IM8: 0 | IN8: 0 | IO8: 24 | IP8: 0 | IQ8: 0 | IR8: 0 | IS8: 0 | IT8: 0 | IU8: 0 | IV8: 0 | IW8: 0 | IX8: 0 | IY8: 0 | IZ8: 0 | JA8: 0 | JB8: 0 | JC8: 0 | JD8: 0 | JE8: 0 | JF8: 0 | JG8: 0 | JH8: 0 | JI8: 0 | JJ8: 0 | JK8: 0 | JL8: 0 | JM8: 0 | JN8: 0 | JO8: 0 | JP8: 0 | JQ8: 4 | JR8: 0 | JS8: 0 | JT8: 0 | JU8: 0 | JV8: 0 | JW8: 0 | JX8: 0 | JY8: 0 | JZ8: 0 | KA8: 0 | KB8: 0 | KC8: 0 | KD8: 1 | KE8: 1 | KF8: 0 | KG8: 0 | KH8: 0 | KI8: 0 | KJ8: 0 | KK8: 0 | KL8: 0 | KM8: 0 | KN8: 0 | KO8: 0 | KP8: 0 | KQ8: 0 | KR8: 0 | KS8: 0 | KT8: 0 | KU8: 0 | KV8: 0 | KW8: 0 | KX8: 0 | KY8: 0 | KZ8: 0 | LA8: 0 | LB8: 0 | LC8: 0 | LD8: 0 | LE8: 0 | LF8: 0 | LG8: 0 | LH8: 0 | LI8: 0 | LJ8: 0 | LK8: 0 | LL8: 0 | LM8: 0 | LN8: 0 | LO8: 0 | LP8: 0 | LQ8: 0 | LR8: 0 | LS8: 0 | LT8: 0 | LU8: 0 | LV8: 0 | LW8: 0 | LX8: 0 | LY8: 0 | LZ8: 0 | MA8: 0 | MB8: 0 | MC8: 0 | MD8: 0 | ME8: 0 | MF8: 0 | MG8: 0 | MH8: 0 | MI8: 0 | MJ8: 0 | MK8: 0 | ML8: 0 | MM8: 0 | MN8: 0 | MO8: 0 | MP8: 0 | MQ8: 0 | MR8: 0 | MS8: 0 | MT8: 0 | MU8: 0 | MV8: 0 | MW8: 0 | MX8: 0 | MY8: 0 | MZ8: 0 | NA8: 0 | NB8: 0 | NC8: 1800
A9: Revenue | B9: 914.5 | C9: 436 | D9: 515 | E9: 168 | F9: 0 | G9: 0 | H9: 0 | I9: 0 | J9: 177.11 | K9: 186.9 | L9: 0 | M9: 0 | N9: 0 | O9: 88.11 | P9: 0 | Q9: 88.11 | R9: 88.11 | S9: 0 | T9: 0 | U9: 0 | V9: 0 | W9: 0 | X9: 0 | Y9: 168.21 | Z9: 0 | AA9: 0 | AB9: 58 | AC9: 58 | AD9: 58 | AE9: 117.23 | AF9: 205.34 | AG9: 117.23 | AH9: 129.1 | AI9: 129.1 | AJ9: 71.1 | AK9: 0 | AL9: 159.21 | AM9: 158 | AN9: 283.91 | AO9: 283.91 | AP9: 370.81 | AQ9: 457.71 | AR9: 173.8 | AS9: 576.57 | AT9: 1965.63 | AU9: 65.91 | AV9: 65.91 | AW9: 0 | AX9: 0 | AY9: 176.22 | AZ9: 254.43 | BA9: 97.9 | BB9: 0 | BC9: 0 | BD9: 88.11 | BE9: 97.9 | BF9: 0 | BG9: 88.11 | BH9: 447.67 | BI9: 0 | BJ9: 0 | BK9: 0 | BL9: 0 | BM9: 0 | BN9: 249.2 | BO9: 729.8 | BP9: 75.65 | BQ9: 75.65 | BR9: 0 | BS9: 0 | BT9: 0 | BU9: 132.55 | BV9: 591.48 | BW9: 0 | BX9: 0 | BY9: 0 | BZ9: 0 | CA9: 0 | CB9: 226.1 | CC9: 793 | CD9: 0 | CE9: 0 | CF9: 0 | CG9: 90.82 | CH9: 90.82 | CI9: 218.15 | CJ9: 366.52 | CK9: 89.69 | CL9: 185.52 | CM9: 89.69 | CN9: 197.6 | CO9: 619.43 | CP9: 1846.06 | CQ9: 2337.08 | CR9: 601.57 | CS9: 366.03 | CT9: 801.87 | CU9: 718.61 | CV9: 1021.64 | CW9: 1202.51 | CX9: 2789.99 | CY9: 607.49 | CZ9: 247.41 | DA9: 452.93 | DB9: 930.63 | DC9: 2942.78 | DD9: 2689.22 | DE9: 2608.32 | DF9: 1557.01 | DG9: 1657.14 | DH9: 1819.7 | DI9: 1450.09 | DJ9: 1856.31 | DK9: 2528.71 | DL9: 2470.17 | DM9: 265.29 | DN9: 758.59 | DO9: 866.5 | DP9: 959.12 | DQ9: 951.34 | DR9: 2869.02 | DS9: 2782.53 | DT9: 81.73 | DU9: 0 | DV9: 0 | DW9: 0 | DX9: 0 | DY9: 117.81 | DZ9: 1771.53 | EA9: 107.91 | EB9: 107.91 | EC9: 107.91 | ED9: 215.82 | EE9: 2187.25 | EF9: 2815.21 | EG9: 2507.63 | EH9: 77.86 | EI9: 293.68 | EJ9: 293.68 | EK9: 215.82 | EL9: 323.73 | EM9: 550.82 | EN9: 3043.9 | EO9: 313.92 | EP9: 0 | EQ9: 0 | ER9: 0 | ES9: 0 | ET9: 0 | EU9: 1930.09 | EV9: 0 | EW9: 98.1 | EX9: 0 | EY9: 0 | EZ9: 896.84 | FA9: 1491.06 | FB9: 1754 | FC9: 109 | FD9: 109 | FE9: 109 | FF9: 109 | FG9: 0 | FH9: 216.1 | FI9: 1418.1 | FJ9: 0 | FK9: 0 | FL9: 0 | FM9: 0 | FN9: 0 | FO9: 249.81 | FP9: 2784.19 | FQ9: 0 | FR9: 0 | FS9: 0 | FT9: 0 | FU9: 0 | FV9: 1227.46 | FW9: 2537.96 | FX9: 109 | FY9: 186.86 | FZ9: 186.86 | GA9: 168.24 | GB9: 0 | GC9: 225.72 | GD9: 1964.97 | GE9: 411.84 | GF9: 98.1 | GG9: 98.1 | GH9: 98.1 | GI9: 98.1 | GJ9: 205.2 | GK9: 579.15 | GL9: 0 | GM9: 0 | GN9: 0 | GO9: 0 | GP9: 0 | GQ9: 714 | GR9: 440.73 | GS9: 313.92 | GT9: 0 | GU9: 186.12 | GV9: 0 | GW9: 0 | GX9: 117.81 | GY9: 1021.02 | GZ9: 411.84 | HA9: 107.91 | HB9: 107.91 | HC9: 205.92 | HD9: 294.03 | HE9: 1130.22 | HF9: 962.33 | HG9: 205.92 | HH9: 0 | HI9: 0 | HJ9: 0 | HK9: 0 | HL9: 471.24 | HM9: 589.05 | HN9: 0 | HO9: 109 | HP9: 228.9 | HQ9: 228.9 | HR9: 228.9 | HS9: 249.9 | HT9: 1341.71 | HU9: 195.34 | HV9: 97.33 | HW9: 0 | HX9: 0 | HY9: 612.7 | HZ9: 2853 | IA9: 3202.1 | IB9: 515.9 | IC9: 0 | ID9: 0 | IE9: 0 | IF9: 0 | IG9: 0 | IH9: 130.9 | II9: 0 | IJ9: 0 | IK9: 0 | IL9: 0 | IM9: 0 | IN9: 0 | IO9: 1402.83 | IP9: 0 | IQ9: 0 | IR9: 0 | IS9: 0 | IT9: 0 | IU9: 0 | IV9: 0 | IW9: 0 | IX9: 0 | IY9: 0 | IZ9: 0 | JA9: 0 | JB9: 0 | JC9: 0 | JD9: 0 | JE9: 0 | JF9: 0 | JG9: 0 | JH9: 0 | JI9: 0 | JJ9: 0 | JK9: 0 | JL9: 0 | JM9: 0 | JN9: 0 | JO9: 0 | JP9: 0 | JQ9: 176.22 | JR9: 0 | JS9: 0 | JT9: 0 | JU9: 0 | JV9: 0 | JW9: 0 | JX9: 0 | JY9: 0 | JZ9: 0 | KA9: 0 | KB9: 0 | KC9: 0 | KD9: 78.21 | KE9: 78.21 | KF9: 0 | KG9: 0 | KH9: 0 | KI9: 0 | KJ9: 0 | KK9: 0 | KL9: 0 | KM9: 0 | KN9: 0 | KO9: 0 | KP9: 0 | KQ9: 0 | KR9: 0 | KS9: 0 | KT9: 0 | KU9: 0 | KV9: 0 | KW9: 0 | KX9: 0 | KY9: 0 | KZ9: 0 | LA9: 0 | LB9: 0 | LC9: 0 | LD9: 0 | LE9: 0 | LF9: 0 | LG9: 0 | LH9: 0 | LI9: 0 | LJ9: 0 | LK9: 0 | LL9: 0 | LM9: 0 | LN9: 0 | LO9: 0 | LP9: 0 | LQ9: 0 | LR9: 0 | LS9: 0 | LT9: 0 | LU9: 0 | LV9: 0 | LW9: 0 | LX9: 0 | LY9: 0 | LZ9: 0 | MA9: 0 | MB9: 0 | MC9: 0 | MD9: 0 | ME9: 0 | MF9: 0 | MG9: 0 | MH9: 0 | MI9: 0 | MJ9: 0 | MK9: 0 | ML9: 0 | MM9: 0 | MN9: 0 | MO9: 0 | MP9: 0 | MQ9: 0 | MR9: 0 | MS9: 0 | MT9: 0 | MU9: 0 | MV9: 0 | MW9: 0 | MX9: 0 | MY9: 0 | MZ9: 0 | NA9: 0 | NB9: 0 | NC9: 112976.28
A10: Turist tax revenue | B10: 42.67 | C10: 17.57 | D10: 20.08 | E10: 5.02 | F10: 0 | G10: 0 | H10: 0 | I10: 0 | J10: 7.53 | K10: 7.53 | L10: 0 | M10: 0 | N10: 0 | O10: 2.51 | P10: 0 | Q10: 2.51 | R10: 2.51 | S10: 0 | T10: 0 | U10: 0 | V10: 0 | W10: 0 | X10: 0 | Y10: 5.02 | Z10: 0 | AA10: 0 | AB10: 5.02 | AC10: 5.02 | AD10: 5.02 | AE10: 12.76 | AF10: 10.18 | AG10: 5.02 | AH10: 7.74 | AI10: 7.74 | AJ10: 2.58 | AK10: 0 | AL10: 7.74 | AM10: 5.16 | AN10: 7.74 | AO10: 7.74 | AP10: 10.32 | AQ10: 12.9 | AR10: 5.16 | AS10: 30.96 | AT10: 110.94 | AU10: 5.16 | AV10: 5.16 | AW10: 0 | AX10: 0 | AY10: 10.32 | AZ10: 10.32 | BA10: 5.16 | BB10: 0 | BC10: 0 | BD10: 5.16 | BE10: 5.16 | BF10: 0 | BG10: 5.16 | BH10: 25.8 | BI10: 0 | BJ10: 0 | BK10: 0 | BL10: 0 | BM10: 0 | BN10: 12.9 | BO10: 38.7 | BP10: 5.16 | BQ10: 5.16 | BR10: 0 | BS10: 0 | BT10: 0 | BU10: 7.74 | BV10: 30.96 | BW10: 0 | BX10: 0 | BY10: 0 | BZ10: 0 | CA10: 0 | CB10: 7.74 | CC10: 23.22 | CD10: 0 | CE10: 0 | CF10: 0 | CG10: 5.16 | CH10: 5.16 | CI10: 10.32 | CJ10: 15.48 | CK10: 5.16 | CL10: 7.74 | CM10: 5.16 | CN10: 10.32 | CO10: 30.96 | CP10: 79.98 | CQ10: 108.36 | CR10: 30.96 | CS10: 18.06 | CT10: 38.7 | CU10: 30.96 | CV10: 40.65 | CW10: 43.65 | CX10: 110.94 | CY10: 23.22 | CZ10: 7.74 | DA10: 18.06 | DB10: 36.12 | DC10: 87.72 | DD10: 110.94 | DE10: 110.94 | DF10: 59.34 | DG10: 59.34 | DH10: 61.92 | DI10: 51.6 | DJ10: 64.5 | DK10: 95.46 | DL10: 103.2 | DM10: 10.32 | DN10: 33.54 | DO10: 38.7 | DP10: 41.28 | DQ10: 43.86 | DR10: 118.68 | DS10: 115.96 | DT10: 5.16 | DU10: 0 | DV10: 0 | DW10: 0 | DX10: 0 | DY10: 5.16 | DZ10: 74.82 | EA10: 5.16 | EB10: 5.16 | EC10: 5.16 | ED10: 10.32 | EE10: 99.5 | EF10: 117.14 | EG10: 107.73 | EH10: 2.51 | EI10: 7.74 | EJ10: 7.74 | EK10: 5.16 | EL10: 10.18 | EM10: 20.5 | EN10: 105.98 | EO10: 15.2 | EP10: 0 | EQ10: 0 | ER10: 0 | ES10: 0 | ET10: 0 | EU10: 68.96 | EV10: 0 | EW10: 5.02 | EX10: 0 | EY10: 0 | EZ10: 45.32 | FA10: 68.33 | FB10: 81.16 | FC10: 5.02 | FD10: 2.51 | FE10: 2.51 | FF10: 5.16 | FG10: 0 | FH10: 10.18 | FI10: 61.36 | FJ10: 0 | FK10: 0 | FL10: 0 | FM10: 0 | FN10: 0 | FO10: 10.04 | FP10: 109.4 | FQ10: 0 | FR10: 0 | FS10: 0 | FT10: 0 | FU10: 0 | FV10: 50.9 | FW10: 102.01 | FX10: 2.51 | FY10: 5.09 | FZ10: 5.09 | GA10: 7.53 | GB10: 0 | GC10: 7.67 | GD10: 73.63 | GE10: 12.83 | GF10: 5.02 | GG10: 5.02 | GH10: 5.02 | GI10: 5.02 | GJ10: 7.74 | GK10: 22.73 | GL10: 0 | GM10: 0 | GN10: 0 | GO10: 0 | GP10: 0 | GQ10: 20.5 | GR10: 20.22 | GS10: 15.2 | GT10: 0 | GU10: 7.53 | GV10: 0 | GW10: 0 | GX10: 5.16 | GY10: 46.02 | GZ10: 20.36 | HA10: 5.16 | HB10: 5.16 | HC10: 7.74 | HD10: 7.6 | HE10: 35.42 | HF10: 35.42 | HG10: 5.16 | HH10: 0 | HI10: 0 | HJ10: 0 | HK10: 0 | HL10: 20.64 | HM10: 23.22 | HN10: 0 | HO10: 5.02 | HP10: 10.18 | HQ10: 10.18 | HR10: 10.18 | HS10: 10.04 | HT10: 52.92 | HU10: 7.74 | HV10: 5.16 | HW10: 0 | HX10: 0 | HY10: 22.59 | HZ10: 95.45 | IA10: 105.56 | IB10: 20.22 | IC10: 0 | ID10: 0 | IE10: 0 | IF10: 0 | IG10: 0 | IH10: 5.16 | II10: 0 | IJ10: 0 | IK10: 0 | IL10: 0 | IM10: 0 | IN10: 0 | IO10: 60.8 | IP10: 0 | IQ10: 0 | IR10: 0 | IS10: 0 | IT10: 0 | IU10: 0 | IV10: 0 | IW10: 0 | IX10: 0 | IY10: 0 | IZ10: 0 | JA10: 0 | JB10: 0 | JC10: 0 | JD10: 0 | JE10: 0 | JF10: 0 | JG10: 0 | JH10: 0 | JI10: 0 | JJ10: 0 | JK10: 0 | JL10: 0 | JM10: 0 | JN10: 0 | JO10: 0 | JP10: 0 | JQ10: 10.18 | JR10: 0 | JS10: 0 | JT10: 0 | JU10: 0 | JV10: 0 | JW10: 0 | JX10: 0 | JY10: 0 | JZ10: 0 | KA10: 0 | KB10: 0 | KC10: 0 | KD10: 2.58 | KE10: 2.58 | KF10: 0 | KG10: 0 | KH10: 0 | KI10: 0 | KJ10: 0 | KK10: 0 | KL10: 0 | KM10: 0 | KN10: 0 | KO10: 0 | KP10: 0 | KQ10: 0 | KR10: 0 | KS10: 0 | KT10: 0 | KU10: 0 | KV10: 0 | KW10: 0 | KX10: 0 | KY10: 0 | KZ10: 0 | LA10: 0 | LB10: 0 | LC10: 0 | LD10: 0 | LE10: 0 | LF10: 0 | LG10: 0 | LH10: 0 | LI10: 0 | LJ10: 0 | LK10: 0 | LL10: 0 | LM10: 0 | LN10: 0 | LO10: 0 | LP10: 0 | LQ10: 0 | LR10: 0 | LS10: 0 | LT10: 0 | LU10: 0 | LV10: 0 | LW10: 0 | LX10: 0 | LY10: 0 | LZ10: 0 | MA10: 0 | MB10: 0 | MC10: 0 | MD10: 0 | ME10: 0 | MF10: 0 | MG10: 0 | MH10: 0 | MI10: 0 | MJ10: 0 | MK10: 0 | ML10: 0 | MM10: 0 | MN10: 0 | MO10: 0 | MP10: 0 | MQ10: 0 | MR10: 0 | MS10: 0 | MT10: 0 | MU10: 0 | MV10: 0 | MW10: 0 | MX10: 0 | MY10: 0 | MZ10: 0 | NA10: 0 | NB10: 0 | NC10: 4591.98
A11: Revenue | B11: 957.17 | C11: 453.57 | D11: 535.08 | E11: 173.02 | F11: 0 | G11: 0 | H11: 0 | I11: 0 | J11: 184.64 | K11: 194.43 | L11: 0 | M11: 0 | N11: 0 | O11: 90.62 | P11: 0 | Q11: 90.62 | R11: 90.62 | S11: 0 | T11: 0 | U11: 0 | V11: 0 | W11: 0 | X11: 0 | Y11: 173.23 | Z11: 0 | AA11: 0 | AB11: 63.02 | AC11: 63.02 | AD11: 63.02 | AE11: 129.99 | AF11: 215.52 | AG11: 122.25 | AH11: 249.91 | AI11: 136.84 | AJ11: 73.68 | AK11: 0 | AL11: 166.95 | AM11: 163.16 | AN11: 291.65 | AO11: 291.65 | AP11: 381.13 | AQ11: 470.61 | AR11: 178.96 | AS11: 607.53 | AT11: 2076.57 | AU11: 257.61 | AV11: 71.07 | AW11: 0 | AX11: 0 | AY11: 186.54 | AZ11: 264.75 | BA11: 103.06 | BB11: 0 | BC11: 0 | BD11: 93.27 | BE11: 103.06 | BF11: 0 | BG11: 93.27 | BH11: 473.47 | BI11: 0 | BJ11: 0 | BK11: 0 | BL11: 0 | BM11: 0 | BN11: 262.1 | BO11: 768.5 | BP11: 80.81 | BQ11: 80.81 | BR11: 0 | BS11: 0 | BT11: 0 | BU11: 140.29 | BV11: 622.44 | BW11: 0 | BX11: 0 | BY11: 0 | BZ11: 0 | CA11: 0 | CB11: 233.84 | CC11: 816.22 | CD11: 0 | CE11: 0 | CF11: 0 | CG11: 95.98 | CH11: 95.98 | CI11: 228.47 | CJ11: 382 | CK11: 94.85 | CL11: 193.26 | CM11: 94.85 | CN11: 207.92 | CO11: 650.39 | CP11: 1926.04 | CQ11: 2445.44 | CR11: 632.53 | CS11: 384.09 | CT11: 840.57 | CU11: 749.57 | CV11: 1062.29 | CW11: 1246.16 | CX11: 2900.93 | CY11: 630.71 | CZ11: 255.15 | DA11: 470.99 | DB11: 966.75 | DC11: 3030.5 | DD11: 2800.16 | DE11: 2719.26 | DF11: 1616.35 | DG11: 1716.48 | DH11: 1881.62 | DI11: 1501.69 | DJ11: 1920.81 | DK11: 2624.17 | DL11: 2573.37 | DM11: 275.61 | DN11: 792.13 | DO11: 905.2 | DP11: 1000.4 | DQ11: 995.2 | DR11: 2987.7 | DS11: 2898.49 | DT11: 86.89 | DU11: 0 | DV11: 0 | DW11: 0 | DX11: 0 | DY11: 122.97 | DZ11: 1846.35 | EA11: 113.07 | EB11: 113.07 | EC11: 113.07 | ED11: 226.14 | EE11: 2286.75 | EF11: 2932.35 | EG11: 2615.36 | EH11: 80.37 | EI11: 301.42 | EJ11: 301.42 | EK11: 220.98 | EL11: 333.91 | EM11: 571.32 | EN11: 3149.88 | EO11: 329.12 | EP11: 0 | EQ11: 0 | ER11: 0 | ES11: 0 | ET11: 0 | EU11: 1999.05 | EV11: 0 | EW11: 103.12 | EX11: 0 | EY11: 0 | EZ11: 942.16 | FA11: 1559.39 | FB11: 1835.16 | FC11: 114.02 | FD11: 111.51 | FE11: 111.51 | FF11: 114.16 | FG11: 0 | FH11: 226.28 | FI11: 1479.46 | FJ11: 0 | FK11: 0 | FL11: 0 | FM11: 0 | FN11: 0 | FO11: 259.85 | FP11: 2893.59 | FQ11: 0 | FR11: 0 | FS11: 0 | FT11: 0 | FU11: 0 | FV11: 1278.36 | FW11: 2639.97 | FX11: 111.51 | FY11: 191.95 | FZ11: 191.95 | GA11: 175.77 | GB11: 0 | GC11: 233.39 | GD11: 2038.6 | GE11: 424.67 | GF11: 103.12 | GG11: 103.12 | GH11: 103.12 | GI11: 103.12 | GJ11: 212.94 | GK11: 601.88 | GL11: 0 | GM11: 0 | GN11: 0 | GO11: 0 | GP11: 0 | GQ11: 734.5 | GR11: 460.95 | GS11: 329.12 | GT11: 0 | GU11: 193.65 | GV11: 0 | GW11: 0 | GX11: 122.97 | GY11: 1067.04 | GZ11: 432.2 | HA11: 113.07 | HB11: 113.07 | HC11: 213.66 | HD11: 301.63 | HE11: 1165.64 | HF11: 997.75 | HG11: 211.08 | HH11: 0 | HI11: 0 | HJ11: 0 | HK11: 0 | HL11: 491.88 | HM11: 612.27 | HN11: 0 | HO11: 114.02 | HP11: 239.08 | HQ11: 239.08 | HR11: 239.08 | HS11: 259.94 | HT11: 1394.63 | HU11: 203.08 | HV11: 102.49 | HW11: 0 | HX11: 0 | HY11: 635.29 | HZ11: 2948.45 | IA11: 3307.66 | IB11: 536.12 | IC11: 0 | ID11: 0 | IE11: 0 | IF11: 0 | IG11: 0 | IH11: 136.06 | II11: 0 | IJ11: 0 | IK11: 0 | IL11: 0 | IM11: 0 | IN11: 0 | IO11: 1463.63 | IP11: 0 | IQ11: 0 | IR11: 0 | IS11: 0 | IT11: 0 | IU11: 0 | IV11: 0 | IW11: 0 | IX11: 0 | IY11: 0 | IZ11: 0 | JA11: 0 | JB11: 0 | JC11: 0 | JD11: 0 | JE11: 0 | JF11: 0 | JG11: 0 | JH11: 0 | JI11: 0 | JJ11: 0 | JK11: 0 | JL11: 0 | JM11: 0 | JN11: 0 | JO11: 0 | JP11: 0 | JQ11: 186.4 | JR11: 0 | JS11: 0 | JT11: 0 | JU11: 0 | JV11: 0 | JW11: 0 | JX11: 0 | JY11: 0 | JZ11: 0 | KA11: 0 | KB11: 0 | KC11: 0 | KD11: 80.79 | KE11: 80.79 | KF11: 0 | KG11: 0 | KH11: 0 | KI11: 0 | KJ11: 0 | KK11: 0 | KL11: 0 | KM11: 0 | KN11: 0 | KO11: 0 | KP11: 0 | KQ11: 0 | KR11: 0 | KS11: 0 | KT11: 0 | KU11: 0 | KV11: 0 | KW11: 0 | KX11: 0 | KY11: 0 | KZ11: 0 | LA11: 0 | LB11: 0 | LC11: 0 | LD11: 0 | LE11: 0 | LF11: 0 | LG11: 0 | LH11: 0 | LI11: 0 | LJ11: 0 | LK11: 0 | LL11: 0 | LM11: 0 | LN11: 0 | LO11: 0 | LP11: 0 | LQ11: 0 | LR11: 0 | LS11: 0 | LT11: 0 | LU11: 0 | LV11: 0 | LW11: 0 | LX11: 0 | LY11: 0 | LZ11: 0 | MA11: 0 | MB11: 0 | MC11: 0 | MD11: 0 | ME11: 0 | MF11: 0 | MG11: 0 | MH11: 0 | MI11: 0 | MJ11: 0 | MK11: 0 | ML11: 0 | MM11: 0 | MN11: 0 | MO11: 0 | MP11: 0 | MQ11: 0 | MR11: 0 | MS11: 0 | MT11: 0 | MU11: 0 | MV11: 0 | MW11: 0 | MX11: 0 | MY11: 0 | MZ11: 0 | NA11: 0 | NB11: 0 | NC11: 117867.87
A12: Total Revenue | B12: 1002.17 | C12: 483.57 | D12: 535.08 | E12: 173.02 | F12: 0 | G12: 0 | H12: 0 | I12: 0 | J12: 214.64 | K12: 209.43 | L12: 0 | M12: 0 | N12: 0 | O12: 105.62 | P12: 0 | Q12: 90.62 | R12: 90.62 | S12: 0 | T12: 0 | U12: 0 | V12: 0 | W12: 0 | X12: 0 | Y12: 173.23 | Z12: 0 | AA12: 0 | AB12: 63.02 | AC12: 63.02 | AD12: 63.02 | AE12: 129.99 | AF12: 230.52 | AG12: 122.25 | AH12: 264.91 | AI12: 136.84 | AJ12: 73.68 | AK12: 0 | AL12: 196.95 | AM12: 178.16 | AN12: 411.65 | AO12: 291.65 | AP12: 381.13 | AQ12: 500.61 | AR12: 178.96 | AS12: 757.53 | AT12: 2316.57 | AU12: 257.61 | AV12: 71.07 | AW12: 0 | AX12: 0 | AY12: 186.54 | AZ12: 294.75 | BA12: 118.06 | BB12: 0 | BC12: 0 | BD12: 123.27 | BE12: 103.06 | BF12: 0 | BG12: 93.27 | BH12: 473.47 | BI12: 0 | BJ12: 0 | BK12: 0 | BL12: 0 | BM12: 0 | BN12: 262.1 | BO12: 768.5 | BP12: 80.81 | BQ12: 80.81 | BR12: 0 | BS12: 0 | BT12: 0 | BU12: 140.29 | BV12: 622.44 | BW12: 0 | BX12: 0 | BY12: 0 | BZ12: 0 | CA12: 0 | CB12: 233.84 | CC12: 816.22 | CD12: 0 | CE12: 0 | CF12: 0 | CG12: 95.98 | CH12: 95.98 | CI12: 228.47 | CJ12: 382 | CK12: 94.85 | CL12: 193.26 | CM12: 94.85 | CN12: 207.92 | CO12: 650.39 | CP12: 1926.04 | CQ12: 2445.44 | CR12: 632.53 | CS12: 384.09 | CT12: 840.57 | CU12: 749.57 | CV12: 1062.29 | CW12: 1246.16 | CX12: 2900.93 | CY12: 630.71 | CZ12: 255.15 | DA12: 470.99 | DB12: 966.75 | DC12: 3030.5 | DD12: 2800.16 | DE12: 2719.26 | DF12: 1616.35 | DG12: 1716.48 | DH12: 1881.62 | DI12: 1501.69 | DJ12: 1920.81 | DK12: 2624.17 | DL12: 2573.37 | DM12: 275.61 | DN12: 792.13 | DO12: 905.2 | DP12: 1000.4 | DQ12: 995.2 | DR12: 2987.7 | DS12: 2898.49 | DT12: 86.89 | DU12: 0 | DV12: 0 | DW12: 0 | DX12: 0 | DY12: 122.97 | DZ12: 1846.35 | EA12: 113.07 | EB12: 113.07 | EC12: 113.07 | ED12: 226.14 | EE12: 2286.75 | EF12: 2932.35 | EG12: 2615.36 | EH12: 80.37 | EI12: 301.42 | EJ12: 301.42 | EK12: 220.98 | EL12: 333.91 | EM12: 571.32 | EN12: 3149.88 | EO12: 329.12 | EP12: 0 | EQ12: 0 | ER12: 0 | ES12: 0 | ET12: 0 | EU12: 1999.05 | EV12: 0 | EW12: 103.12 | EX12: 0 | EY12: 0 | EZ12: 942.16 | FA12: 1559.39 | FB12: 1835.16 | FC12: 114.02 | FD12: 111.51 | FE12: 111.51 | FF12: 114.16 | FG12: 0 | FH12: 226.28 | FI12: 1479.46 | FJ12: 0 | FK12: 0 | FL12: 0 | FM12: 0 | FN12: 0 | FO12: 259.85 | FP12: 2893.59 | FQ12: 0 | FR12: 0 | FS12: 0 | FT12: 0 | FU12: 0 | FV12: 1278.36 | FW12: 2639.97 | FX12: 111.51 | FY12: 191.95 | FZ12: 191.95 | GA12: 175.77 | GB12: 0 | GC12: 233.39 | GD12: 2038.6 | GE12: 424.67 | GF12: 103.12 | GG12: 103.12 | GH12: 103.12 | GI12: 103.12 | GJ12: 212.94 | GK12: 601.88 | GL12: 0 | GM12: 0 | GN12: 0 | GO12: 0 | GP12: 0 | GQ12: 734.5 | GR12: 460.95 | GS12: 329.12 | GT12: 0 | GU12: 193.65 | GV12: 0 | GW12: 0 | GX12: 122.97 | GY12: 1067.04 | GZ12: 432.2 | HA12: 113.07 | HB12: 113.07 | HC12: 213.66 | HD12: 301.63 | HE12: 1165.64 | HF12: 997.75 | HG12: 211.08 | HH12: 0 | HI12: 0 | HJ12: 0 | HK12: 0 | HL12: 491.88 | HM12: 612.27 | HN12: 0 | HO12: 114.02 | HP12: 239.08 | HQ12: 239.08 | HR12: 239.08 | HS12: 259.94 | HT12: 1394.63 | HU12: 203.08 | HV12: 102.49 | HW12: 0 | HX12: 0 | HY12: 635.29 | HZ12: 2948.45 | IA12: 3307.66 | IB12: 536.12 | IC12: 0 | ID12: 0 | IE12: 0 | IF12: 0 | IG12: 0 | IH12: 136.06 | II12: 0 | IJ12: 0 | IK12: 0 | IL12: 0 | IM12: 0 | IN12: 0 | IO12: 1463.63 | IP12: 0 | IQ12: 0 | IR12: 0 | IS12: 0 | IT12: 0 | IU12: 0 | IV12: 0 | IW12: 0 | IX12: 0 | IY12: 0 | IZ12: 0 | JA12: 0 | JB12: 0 | JC12: 0 | JD12: 0 | JE12: 0 | JF12: 0 | JG12: 0 | JH12: 0 | JI12: 0 | JJ12: 0 | JK12: 0 | JL12: 0 | JM12: 0 | JN12: 0 | JO12: 0 | JP12: 0 | JQ12: 186.4 | JR12: 0 | JS12: 0 | JT12: 0 | JU12: 0 | JV12: 0 | JW12: 0 | JX12: 0 | JY12: 0 | JZ12: 0 | KA12: 0 | KB12: 0 | KC12: 0 | KD12: 80.79 | KE12: 80.79 | KF12: 0 | KG12: 0 | KH12: 0 | KI12: 0 | KJ12: 0 | KK12: 0 | KL12: 0 | KM12: 0 | KN12: 0 | KO12: 0 | KP12: 0 | KQ12: 0 | KR12: 0 | KS12: 0 | KT12: 0 | KU12: 0 | KV12: 0 | KW12: 0 | KX12: 0 | KY12: 0 | KZ12: 0 | LA12: 0 | LB12: 0 | LC12: 0 | LD12: 0 | LE12: 0 | LF12: 0 | LG12: 0 | LH12: 0 | LI12: 0 | LJ12: 0 | LK12: 0 | LL12: 0 | LM12: 0 | LN12: 0 | LO12: 0 | LP12: 0 | LQ12: 0 | LR12: 0 | LS12: 0 | LT12: 0 | LU12: 0 | LV12: 0 | LW12: 0 | LX12: 0 | LY12: 0 | LZ12: 0 | MA12: 0 | MB12: 0 | MC12: 0 | MD12: 0 | ME12: 0 | MF12: 0 | MG12: 0 | MH12: 0 | MI12: 0 | MJ12: 0 | MK12: 0 | ML12: 0 | MM12: 0 | MN12: 0 | MO12: 0 | MP12: 0 | MQ12: 0 | MR12: 0 | MS12: 0 | MT12: 0 | MU12: 0 | MV12: 0 | MW12: 0 | MX12: 0 | MY12: 0 | MZ12: 0 | NA12: 0 | NB12: 0 | NC12: €118.692,87
A14: Arrival | BE14: 1 | BF14: 0 | BG14: 1 | BH14: 4 | BI14: 0 | BJ14: 0 | BK14: 0 | BL14: 0 | BM14: 0 | BN14: 3 | BO14: 6 | BP14: 0 | BQ14: 0 | BR14: 0 | BS14: 0 | BT14: 0 | BU14: 2 | BV14: 4 | BW14: 0
A15: Departure | BE15: 1 | BF15: 1 | BG15: 0 | BH15: 0 | BI15: 5 | BJ15: 0 | BK15: 0 | BL15: 0 | BM15: 0 | BN15: 0 | BO15: 1 | BP15: 7 | BQ15: 0 | BR15: 1 | BS15: 0 | BT15: 0 | BU15: 0 | BV15: 0 | BW15: 7
A17: Weather | B17: 10ºC
A18: Partly Cloud
A19: Humidade | B19: 0.71
A20: ventos | B20: 25 km/h

Sheet 2026_Formulas
B1: 01-01-2026 | C1: 02-01-2026 | D1: 03-01-2026 | E1: 04-01-2026 | F1: 05-01-2026 | G1: 06-01-2026 | H1: 07-01-2026 | I1: 08-01-2026 | J1: 09-01-2026 | K1: 10-01-2026 | L1: 11-01-2026 | M1: 12-01-2026 | N1: 13-01-2026 | O1: 14-01-2026 | P1: 15-01-2026 | Q1: 16-01-2026 | R1: 17-01-2026 | S1: 18-01-2026 | T1: 19-01-2026 | U1: 20-01-2026 | V1: 21-01-2026 | W1: 22-01-2026 | X1: 23-01-2026 | Y1: 24-01-2026 | Z1: 25-01-2026 | AA1: 26-01-2026 | AB1: 27-01-2026 | AC1: 28-01-2026 | AD1: 29-01-2026 | AE1: 30-01-2026 | AF1: 31-01-2026 | AG1: 01-02-2026 | AH1: 02-02-2026 | AI1: 03-02-2026 | AJ1: 04-02-2026 | AK1: 05-02-2026 | AL1: 06-02-2026 | AM1: 07-02-2026 | AN1: 08-02-2026 | AO1: 09-02-2026 | AP1: 10-02-2026 | AQ1: 11-02-2026 | AR1: 12-02-2026 | AS1: 13-02-2026 | AT1: 14-02-2026 | AU1: 15-02-2026 | AV1: 16-02-2026 | AW1: 17-02-2026 | AX1: 18-02-2026 | AY1: 19-02-2026 | AZ1: 20-02-2026 | BA1: 21-02-2026 | BB1: 22-02-2026 | BC1: 23-02-2026 | BD1: 24-02-2026 | BE1: 25-02-2026 | BF1: 26-02-2026 | BG1: 27-02-2026 | BH1: 28-02-2026 | BI1: 01-03-2026 | BJ1: 02-03-2026 | BK1: 03-03-2026 | BL1: 04-03-2026 | BM1: 05-03-2026 | BN1: 06-03-2026 | BO1: 07-03-2026 | BP1: 08-03-2026 | BQ1: 09-03-2026 | BR1: 10-03-2026 | BS1: 11-03-2026 | BT1: 12-03-2026 | BU1: 13-03-2026 | BV1: 14-03-2026 | BW1: 15-03-2026 | BX1: 16-03-2026 | BY1: 17-03-2026 | BZ1: 18-03-2026 | CA1: 19-03-2026 | CB1: 20-03-2026 | CC1: 21-03-2026 | CD1: 22-03-2026 | CE1: 23-03-2026 | CF1: 24-03-2026 | CG1: 25-03-2026 | CH1: 26-03-2026 | CI1: 27-03-2026 | CJ1: 28-03-2026 | CK1: 29-03-2026 | CL1: 30-03-2026 | CM1: 31-03-2026 | CN1: 01-04-2026 | CO1: 02-04-2026 | CP1: 03-04-2026 | CQ1: 04-04-2026 | CR1: 05-04-2026 | CS1: 06-04-2026 | CT1: 07-04-2026 | CU1: 08-04-2026 | CV1: 09-04-2026 | CW1: 10-04-2026 | CX1: 11-04-2026 | CY1: 12-04-2026 | CZ1: 13-04-2026 | DA1: 14-04-2026 | DB1: 15-04-2026 | DC1: 16-04-2026 | DD1: 17-04-2026 | DE1: 18-04-2026 | DF1: 19-04-2026 | DG1: 20-04-2026 | DH1: 21-04-2026 | DI1: 22-04-2026 | DJ1: 23-04-2026 | DK1: 24-04-2026 | DL1: 25-04-2026 | DM1: 26-04-2026 | DN1: 27-04-2026 | DO1: 28-04-2026 | DP1: 29-04-2026 | DQ1: 30-04-2026 | DR1: 01-05-2026 | DS1: 02-05-2026 | DT1: 03-05-2026 | DU1: 04-05-2026 | DV1: 05-05-2026 | DW1: 06-05-2026 | DX1: 07-05-2026 | DY1: 08-05-2026 | DZ1: 09-05-2026 | EA1: 10-05-2026 | EB1: 11-05-2026 | EC1: 12-05-2026 | ED1: 13-05-2026 | EE1: 14-05-2026 | EF1: 15-05-2026 | EG1: 16-05-2026 | EH1: 17-05-2026 | EI1: 18-05-2026 | EJ1: 19-05-2026 | EK1: 20-05-2026 | EL1: 21-05-2026 | EM1: 22-05-2026 | EN1: 23-05-2026 | EO1: 24-05-2026 | EP1: 25-05-2026 | EQ1: 26-05-2026 | ER1: 27-05-2026 | ES1: 28-05-2026 | ET1: 29-05-2026 | EU1: 30-05-2026 | EV1: 31-05-2026 | EW1: 01-06-2026 | EX1: 02-06-2026 | EY1: 03-06-2026 | EZ1: 04-06-2026 | FA1: 05-06-2026 | FB1: 06-06-2026 | FC1: 07-06-2026 | FD1: 08-06-2026 | FE1: 09-06-2026 | FF1: 10-06-2026 | FG1: 11-06-2026 | FH1: 12-06-2026 | FI1: 13-06-2026 | FJ1: 14-06-2026 | FK1: 15-06-2026 | FL1: 16-06-2026 | FM1: 17-06-2026 | FN1: 18-06-2026 | FO1: 19-06-2026 | FP1: 20-06-2026 | FQ1: 21-06-2026 | FR1: 22-06-2026 | FS1: 23-06-2026 | FT1: 24-06-2026 | FU1: 25-06-2026 | FV1: 26-06-2026 | FW1: 27-06-2026 | FX1: 28-06-2026 | FY1: 29-06-2026 | FZ1: 30-06-2026 | GA1: 01-07-2026 | GB1: 02-07-2026 | GC1: 03-07-2026 | GD1: 04-07-2026 | GE1: 05-07-2026 | GF1: 06-07-2026 | GG1: 07-07-2026 | GH1: 08-07-2026 | GI1: 09-07-2026 | GJ1: 10-07-2026 | GK1: 11-07-2026 | GL1: 12-07-2026 | GM1: 13-07-2026 | GN1: 14-07-2026 | GO1: 15-07-2026 | GP1: 16-07-2026 | GQ1: 17-07-2026 | GR1: 18-07-2026 | GS1: 19-07-2026 | GT1: 20-07-2026 | GU1: 21-07-2026 | GV1: 22-07-2026 | GW1: 23-07-2026 | GX1: 24-07-2026 | GY1: 25-07-2026 | GZ1: 26-07-2026 | HA1: 27-07-2026 | HB1: 28-07-2026 | HC1: 29-07-2026 | HD1: 30-07-2026 | HE1: 31-07-2026 | HF1: 01-08-2026 | HG1: 02-08-2026 | HH1: 03-08-2026 | HI1: 04-08-2026 | HJ1: 05-08-2026 | HK1: 06-08-2026 | HL1: 07-08-2026 | HM1: 08-08-2026 | HN1: 09-08-2026 | HO1: 10-08-2026 | HP1: 11-08-2026 | HQ1: 12-08-2026 | HR1: 13-08-2026 | HS1: 14-08-2026 | HT1: 15-08-2026 | HU1: 16-08-2026 | HV1: 17-08-2026 | HW1: 18-08-2026 | HX1: 19-08-2026 | HY1: 20-08-2026 | HZ1: 21-08-2026 | IA1: 22-08-2026 | IB1: 23-08-2026 | IC1: 24-08-2026 | ID1: 25-08-2026 | IE1: 26-08-2026 | IF1: 27-08-2026 | IG1: 28-08-2026 | IH1: 29-08-2026 | II1: 30-08-2026 | IJ1: 31-08-2026 | IK1: 01-09-2026 | IL1: 02-09-2026 | IM1: 03-09-2026 | IN1: 04-09-2026 | IO1: 05-09-2026 | IP1: 06-09-2026 | IQ1: 07-09-2026 | IR1: 08-09-2026 | IS1: 09-09-2026 | IT1: 10-09-2026 | IU1: 11-09-2026 | IV1: 12-09-2026 | IW1: 13-09-2026 | IX1: 14-09-2026 | IY1: 15-09-2026 | IZ1: 16-09-2026 | JA1: 17-09-2026 | JB1: 18-09-2026 | JC1: 19-09-2026 | JD1: 20-09-2026 | JE1: 21-09-2026 | JF1: 22-09-2026 | JG1: 23-09-2026 | JH1: 24-09-2026 | JI1: 25-09-2026 | JJ1: 26-09-2026 | JK1: 27-09-2026 | JL1: 28-09-2026 | JM1: 29-09-2026 | JN1: 30-09-2026 | JO1: 01-10-2026 | JP1: 02-10-2026 | JQ1: 03-10-2026 | JR1: 04-10-2026 | JS1: 05-10-2026 | JT1: 06-10-2026 | JU1: 07-10-2026 | JV1: 08-10-2026 | JW1: 09-10-2026 | JX1: 10-10-2026 | JY1: 11-10-2026 | JZ1: 12-10-2026 | KA1: 13-10-2026 | KB1: 14-10-2026 | KC1: 15-10-2026 | KD1: 16-10-2026 | KE1: 17-10-2026 | KF1: 18-10-2026 | KG1: 19-10-2026 | KH1: 20-10-2026 | KI1: 21-10-2026 | KJ1: 22-10-2026 | KK1: 23-10-2026 | KL1: 24-10-2026 | KM1: 25-10-2026 | KN1: 26-10-2026 | KO1: 27-10-2026 | KP1: 28-10-2026 | KQ1: 29-10-2026 | KR1: 30-10-2026 | KS1: 31-10-2026 | KT1: 01-11-2026 | KU1: 02-11-2026 | KV1: 03-11-2026 | KW1: 04-11-2026 | KX1: 05-11-2026 | KY1: 06-11-2026 | KZ1: 07-11-2026 | LA1: 08-11-2026 | LB1: 09-11-2026 | LC1: 10-11-2026 | LD1: 11-11-2026 | LE1: 12-11-2026 | LF1: 13-11-2026 | LG1: 14-11-2026 | LH1: 15-11-2026 | LI1: 16-11-2026 | LJ1: 17-11-2026 | LK1: 18-11-2026 | LL1: 19-11-2026 | LM1: 20-11-2026 | LN1: 21-11-2026 | LO1: 22-11-2026 | LP1: 23-11-2026 | LQ1: 24-11-2026 | LR1: 25-11-2026 | LS1: 26-11-2026 | LT1: 27-11-2026 | LU1: 28-11-2026 | LV1: 29-11-2026 | LW1: 30-11-2026 | LX1: 01-12-2026 | LY1: 02-12-2026 | LZ1: 03-12-2026 | MA1: 04-12-2026 | MB1: 05-12-2026 | MC1: 06-12-2026 | MD1: 07-12-2026 | ME1: 08-12-2026 | MF1: 09-12-2026 | MG1: 10-12-2026 | MH1: 11-12-2026 | MI1: 12-12-2026 | MJ1: 13-12-2026 | MK1: 14-12-2026 | ML1: 15-12-2026 | MM1: 16-12-2026 | MN1: 17-12-2026 | MO1: 18-12-2026 | MP1: 19-12-2026 | MQ1: 20-12-2026 | MR1: 21-12-2026 | MS1: 22-12-2026 | MT1: 23-12-2026 | MU1: 24-12-2026 | MV1: 25-12-2026 | MW1: 26-12-2026 | MX1: 27-12-2026 | MY1: 28-12-2026 | MZ1: 29-12-2026 | NA1: 30-12-2026 | NB1: 31-12-2026 | NC1: Total
